Workbook

Sheet Dashboard
C2: =Main!B2 -> #VALUE!
B3: Operating margin | C3: =SUM(Model!M84:P84)/SUM(Model!M69:P69) -> 0.056094961
B4: Return on Assets
B5: Return on Equity | C5: =Model!W101/Model!W132 -> 0.038737897
B6: Revenue | C6: =Model!W69 -> 1493673
B7: 4-year Revenue CAGR | C7: =Model!Z68 -> 0.2365166
B8: Gross Profit | C8: =Model!W69+Model!W74 -> 565776
B9: Total Debt/Equity | C9: =(Model!O143+Model!O135)/Model!O134 -> 0.2743066
B10: Book Value Per Share
B11: 52 Week Change
B12: Market Cap
B13: Trailing P/E
B14: Price/Sales
B15: Price/Book | C15: =Main!C16 -> 1.6663525

Sheet Main
B1: Financials are presented in euros | D1: =C3*62526.632 -> 1535028.8 | F1: Reinach (Kanton Aargau, Schweiz)
B2: #VALUE! | D2: #VALUE! | E2: #VALUE! | F2: Engineering services/ Highly demanding aerostructures | H2: Revenue | I2: EBITDA | J2: Rev Growth | K2: EBITDA margin | L2: 2025 EV/EBITDA
B3: Price | C3: {=_FV(B2,"Price")} -> 24.55 | D3: {=_FV(D2,"Price")} -> 1.2639 | E3: {=_FV(E2,"Price")} -> 1.0832 | F3: Recycling & cast house (where recyclables ar emelted) | G3: 2020 | H3: 265 | I3: 43.3 | K3: =I3/H3 -> 0.16339623
B4: Market cap CHF | C4: =C3*C11 -> 1535028.8 | F4: Extrusion (shaping metals through a shaped die) | G4: 2021 | H4: 285 | I4: 42.9 | J4: =H4/H3-1 -> 0.075471698 | K4: =I4/H4 -> 0.15052632
B5: Market cap | C5: =C4*E3 -> 1662743.2 | D5: =C5*D3 -> 2101541.1 | E5: #VALUE! | F5: Machining | G5: 2022 | H5: 637 | I5: 69.4 | J5: =H5/H4-1 -> 1.2350877 | K5: =I5/H5 -> 0.10894819
B6: Debt | C6: =Model!Y135+Model!Y143+Model!Y136+Model!Y144 -> 240879 | E6: {=_FV(E5,"Price")} -> 1.1665 | F6: Surface Finishing (SF) Treatment & painting | G6: 2023 | H6: 705 | I6: 89.2 | J6: =H6/H5-1 -> 0.10675039 | K6: =I6/H6 -> 0.12652482
B7: Cash | C7: =-Model!Y125 -> -112759 | F7: Subassembly | G7: 2024 | H7: 816 | I7: 130.5 | J7: =H7/H6-1 -> 0.15744681 | K7: =I7/H7 -> 0.15992647
B8: (+) Net Debt | C8: =C6+C7 -> 128120 | G8: 2025 | H8: 971 | I8: 161 | J8: =H8/H7-1 -> 0.18995098 | K8: =I8/H8 -> 0.16580844
B9: (+) Noncontrolling | C9: =Model!Y133 -> 15598
B10: EV (Takeover value) | C10: =C5+C8+C9 -> 1806461.2 | D10: =C10*E6 -> 2107237 | E10: =2300000/C10-1 -> 0.27320752 | G10: 2026e | H10: =H8*(1+J10) -> 1116.65 | I10: =H10*K10 -> 200.997 | J10: 0.15 | K10: =Model!AA80 -> 0.18 | L10: =($C$10/1000)/I10 -> 8.9875034
B11: Shares outstanding | C11: =Model!Y104 -> 62526.632 | D11: =C3*C11 -> 1535028.8 | G11: 2027e | H11: =H10*(1+J11) -> 1228.315 | I11: =H11*K11 -> 184.24725 | J11: 0.1 | K11: =Model!AB80 -> 0.15 | L11: =($C$10/1000)/I11 -> 9.8045491
B12: P/E | C12: {=_FV(B2,"P/E",TRUE)} -> 30.6875 | F12: Alpine Metal Tech GmbH - bought 47% interest in 2022. Bought rest of the shares in 8/19/2024. Has full ownership. | G12: 2028e | H12: =H11*(1+J12) -> 1351.1465 | I12: =H12*K12 -> 216.18344 | J12: 0.1 | K12: =Model!AC80 -> 0.16 | L12: =($C$10/1000)/I12 -> 8.3561498
B13: Alt P/E | C13: =C3/Model!R105 -> 29.914096 | G13: 2029e | H13: =H12*(1+J13) -> 1486.2612 | I13: =H13*K13 -> 252.6644 | J13: 0.1 | K13: =Model!AD80 -> 0.17 | L13: =($C$10/1000)/I13 -> 7.1496469
B14: BV | C14: =Model!Y134 -> 997834 | F14: Majority Shareholder - Dr. Michael Tojner | G14: 2030e | H14: =H13*(1+J14) -> 1634.8873 | I14: =H14*K14 -> 326.97745 | J14: 0.1 | K14: =Model!AE80 -> 0.2 | L14: =($C$10/1000)/I14 -> 5.5247272
B15: BVPS | C15: =C14/C11 -> 15.958544
B16: P/BV | C16: =(C3*E3)/C15 -> 1.6663525 | G16: 2027 analysis
I17: Market pricing in
B18: FCF (FY2025) | C18: =Model!Y184 -> 92753 | F18: Investees | G18: EBITDA forecast) | I18: =I11 -> 184.24725
B19: FCFPS (FY2024) | C19: =C18/C11 -> 1.4834159 | F19: Alpine Metal Tech GmbH (wholly owned sub) | G19: Multiple | I19: 10
B20: P/FCF | C20: =C3/C19 -> 16.549641 | F20: Belairbus NV (129,000 Eur. BV on balance sheet) | G20: Implied EV | I20: =I19*$I$18 -> 1842.4725
B21: PPE | C21: =Model!P109 -> 650763 | F21: Flabel Corporation NV | G21: Net debt | I21: 100
B22: FY2025 EBITDA | C22: =Model!Y78 -> 160592.15 | F22: BeLighting NV | G22: Implied market cap | I22: =I20-I21 -> 1742.4725
B23: EV/EBITDA | C23: =C10/Model!R78 -> 9.4060067 | G23: PPS | I23: =I22/($C$11/1000) -> 27.867685
B24: Backlog: | C24: Unknown | F24: Seeking to divest energy segment at favorable point in market cycle | G24: MOM | I24: =I23/$C$3 -> 1.1351399
F25: 35 offers on the table - 39:00 on Q2 2025 call | I25: =I23/1.6 -> 17.417303
I26: =I25/$C$3 -> 0.70946246
F27: Aerostructures Product line: Aluminum, titanium, Composites
F28: Fuselage Floor Grid | H28: Revenue | I28: EBITDA | J28: Rev Growth | K28: EBITDA margin | L28: 2025 EV/EBITDA
F29: Fuselage Stringers | G29: 2020 | H29: 265 | I29: 43.3 | K29: =I29/H29 -> 0.16339623
F30: Seat Track | G30: 2021 | H30: 285 | I30: 42.9 | J30: =H30/H29-1 -> 0.075471698 | K30: =I30/H30 -> 0.15052632
F31: Engine Rings | G31: 2022 | H31: 637 | I31: 69.4 | J31: =H31/H30-1 -> 1.2350877 | K31: =I31/H31 -> 0.10894819
F32: Wing Structures | G32: 2023 | H32: 705 | I32: 89.2 | J32: =H32/H31-1 -> 0.10675039 | K32: =I32/H32 -> 0.12652482
F33: False Rail | G33: 2024 | H33: 816 | I33: 130.5 | J33: =H33/H32-1 -> 0.15744681 | K33: =I33/H33 -> 0.15992647
F34: Landing Gear (737), Engine parts (737), High Lift Mechanisms | G34: 2025 | H34: 971 | I34: 161 | J34: =H34/H33-1 -> 0.18995098 | K34: =I34/H34 -> 0.16580844
F35: Aerostructure Revenue target (FY2025): 850 Eur. | G35: 2026e | H35: =H34*(1+J35) -> 1116.65 | I35: =H35*K35 -> 223.33 | J35: 0.15 | K35: 0.2 | L35: =($C$10/1000)/I35 -> 8.088753
C36: 35 | G36: 2027e | H36: =H35*(1+J36) -> 1250.648 | I36: =H36*K36 -> 250.1296 | J36: 0.12 | K36: 0.2 | L36: =($C$10/1000)/I36 -> 7.2221009
C37: =C3/C36-1 -> -0.29857143 | G37: 2028e | H37: =H36*(1+J37) -> 1375.7128 | I37: =H37*K37 -> 275.14256 | J37: 0.1 | K37: 0.2 | L37: =($C$10/1000)/I37 -> 6.5655463
G38: 2029e | H38: =H37*(1+J38) -> 1513.2841 | I38: =H38*K38 -> 302.65682 | J38: 0.1 | K38: 0.2 | L38: =($C$10/1000)/I38 -> 5.9686784
G39: 2030e | H39: =H38*(1+J39) -> 1664.6125 | I39: =H39*K39 -> 332.9225 | J39: 0.1 | K39: 0.2 | L39: =($C$10/1000)/I39 -> 5.4260713
G41: 2027 analysis
...

Sheet Model
C2: Q1'2022 | D2: Q2'2022 | E2: Q3'2022 | F2: Q4'2022 | G2: Q1'2023 | H2: Q2'2023 | I2: Q3'2023 | J2: Q4'2023 | K2: Q1'2024 | L2: Q2'2024 | M2: Q3'2024 | N2: Q4'2024 | O2: Q1'2025 | P2: Q2'2025 | Q2: Q3'2025 | R2: TTM Figures | T2: FY2021 | U2: FY2022 | V2: FY2023 | W2: FY2024 | X2: FY2024-restated | Y2: FY2025 | Z2: CAGR: | AA2: FY2026 | AB2: FY2027 | AC2: FY2028 | AD2: FY2029 | AE2: FY2030
A3: X | B3: SEGMENT
B4: Aerostructures
B5: Net Sales | C5: 89358 | D5: =256935-C5 -> 167577 | E5: =433174-D5-C5 -> 176239 | F5: =U5-E5-D5-C5 -> 202349 | G5: 166389 | H5: =332024-G5 -> 165635 | I5: =496727-H5-G5 -> 164703 | J5: =V5-I5-H5-G5 -> 206340 | K5: 207384 | L5: =407878-K5 -> 200494 | M5: =610539-L5-K5 -> 202661 | N5: =W5-M5-L5-K5 -> 203526 | O5: 221323 | P5: =429903-O5 -> 208580 | Q5: =649100-P5-O5 -> 219197 | R5: =Q5+P5+O5+N5 -> 852626 | T5: 284587 | U5: 635523 | V5: 703067 | W5: 814065 | Y5: 881272 | Z5: =((W5/T5)^(1/(2024-2021)))-1 -> 0.41954122 | AA5: 1000000
B6: Intersegment | C6: 519 | D6: =572-C6 -> 53 | E6: =648-D6-C6 -> 76 | F6: =U6-E6-D6-C6 -> 256 | G6: 371 | H6: =695-G6 -> 324 | I6: =1010-H6-G6 -> 315 | J6: =V6-I6-H6-G6 -> 452 | K6: 389 | L6: =1102-K6 -> 713 | M6: =1462-L6-K6 -> 360 | N6: =W6-M6-L6-K6 -> 92 | O6: 0 | P6: 0 | Q6: 0 | R6: =Q6+P6+O6+N6 -> 92 | T6: 378 | U6: 904 | V6: 1462 | W6: 1554 | Y6: 0 | AA6: 0
B7: Sales | C7: =C6+C5 -> 89877 | D7: =D6+D5 -> 167630 | E7: =E6+E5 -> 176315 | F7: =F6+F5 -> 202605 | G7: =G6+G5 -> 166760 | H7: =H6+H5 -> 165959 | I7: =I6+I5 -> 165018 | J7: =J6+J5 -> 206792 | ... R7: =R6+R5 -> 852718 | T7: =T6+T5 -> 284965 | U7: =U6+U5 -> 636427 | V7: =V6+V5 -> 704529 | W7: =W6+W5 -> 815619 | Y7: =Y6+Y5 -> 881272 | AA7: =AA6+AA5 -> 1000000 | AB7: =AA7*(1+AB8) -> 1100000 | AC7: =AB7*(1+AC8) -> 1265000 | AD7: =AC7*(1+AD8) -> 1429450 | AE7: =AD7*(1+AE8) -> 1572395
B8: Net Sales Growth Y/Y | R8: =R7/W7-1 -> 0.045485699 | U8: =U5/T5-1 -> 1.2331414 | V8: =V5/U5-1 -> 0.10628097 | W8: =W5/V5-1 -> 0.15787685 | Y8: =Y5/W5-1 -> 0.08255729 | AA8: =AA7/Y7-1 -> 0.13472345 | AB8: 0.1 | AC8: 0.15 | AD8: 0.13 | AE8: 0.1
B9: EBITDA | C9: 11678 | D9: =24586-C9 -> 12908 | E9: =32702-D9-C9 -> 8116 | F9: =U9-E9-D9-C9 -> 33006 | G9: 13452 | H9: =35171-G9 -> 21719 | I9: =52695-H9-G9 -> 17524 | J9: =V9-I9-H9-G9 -> 20874 | K9: 29287 | L9: =60097-K9 -> 30810 | M9: =90888-L9-K9 -> 30791 | N9: =W9-M9-L9-K9 -> 36147 | O9: 39812 | P9: =76421-O9 -> 36609 | Q9: =111200-P9-O9 -> 34779 | R9: =Q9+P9+O9+N9 -> 147347 | T9: 35127 | U9: 65708 | V9: 73569 | W9: 127035 | Y9: 159811 | Z9: =((W9/T9)^(1/(2024-2021)))-1 -> 0.53494957 | AA9: 185000
B10: Margin% | C10: =C9/C$7 -> 0.12993313 | D10: =D9/D$7 -> 0.077002923 | E10: =E9/E$7 -> 0.046031251 | F10: =F9/F$7 -> 0.16290812 | G10: =G9/G$7 -> 0.080666827 | H10: =H9/H$7 -> 0.13086967 | I10: =I9/I$7 -> 0.10619448 | J10: =J9/J$7 -> 0.10094201 | ... R10: =R9/R$7 -> 0.17279687 | T10: =T9/T$7 -> 0.12326777 | U10: =U9/U$7 -> 0.10324515 | V10: =V9/V$7 -> 0.10442295 | W10: =W9/W$7 -> 0.15575287 | Y10: =Y9/Y$7 -> 0.18134129 | AA10: =AA9/AA$7 -> 0.185
B11: D&A | C11: -14970 | D11: =-37801-C11 -> -22831 | E11: =-62307-D11-C11 -> -24506 | F11: =U11-E11-D11-C11 -> -27111 | G11: -22983 | H11: =-42109-G11 -> -19126 | I11: =-64593-H11-G11 -> -22484 | J11: =V11-I11-H11-G11 -> -17934 | K11: -20244 | L11: =-41789-K11 -> -21545 | M11: =-62487-L11-K11 -> -20698 | N11: =W11-M11-L11-K11 -> -20512 | O11: -21520 | P11: =-42525-O11 -> -21005 | T11: -54104 | U11: -89418 | V11: -82527 | W11: -82999 | Y11: -87106
B12: Margin% | C12: =-C11/C$7 -> 0.16656097 | D12: =-D11/D$7 -> 0.13619877 | E12: =-E11/E$7 -> 0.13898988 | F12: =-F11/F$7 -> 0.1338121 | G12: =-G11/G$7 -> 0.13782082 | H12: =-H11/H$7 -> 0.11524533 | I12: =-I11/I$7 -> 0.1362518 | J12: =-J11/J$7 -> 0.086724825 | ... P12: =-P11/P$7 -> 0.10070477 | T12: =-T11/T$7 -> 0.18986191 | U12: =-U11/U$7 -> 0.14050001 | V12: =-V11/V$7 -> 0.11713783 | W12: =-W11/W$7 -> 0.10176197 | Y12: =-Y11/Y$7 -> 0.09884122
B13: Investments | C13: 16369 | D13: =30538-C13 -> 14169 | E13: =49043-D13-C13 -> 18505 | F13: =U13-E13-D13-C13 -> 28179 | G13: 12492 | H13: =24312-G13 -> 11820 | I13: =34871-H13-G13 -> 10559 | J13: =V13-I13-H13-G13 -> 19149 | K13: 11805 | L13: =25517-K13 -> 13712 | M13: =39783-L13-K13 -> 14266 | N13: =W13-M13-L13-K13 -> 33499 | O13: 23138 | P13: =36460-O13 -> 13322 | T13: 100787 | U13: 77222 | V13: 54020 | W13: 73282 | Y13: 68161
B14: Share of rev% | C14: =C13/C$7 -> 0.18212668 | D14: =D13/D$7 -> 0.084525443 | E14: =E13/E$7 -> 0.1049542 | F14: =F13/F$7 -> 0.13908344 | G14: =G13/G$7 -> 0.07491005 | H14: =H13/H$7 -> 0.07122241 | I14: =I13/I$7 -> 0.063986959 | J14: =J13/J$7 -> 0.092600294 | ... P14: =P13/P$7 -> 0.063869978 | T14: =T13/T$7 -> 0.35368203 | U14: =U13/U$7 -> 0.12133678 | V14: =V13/V$7 -> 0.076675339 | W14: =W13/W$7 -> 0.089848324 | Y14: =Y13/Y$7 -> 0.077343885
B15: Valuation Multiple | Y15: 10
B16: Segment Value | Y16: =Y9*Y15 -> 1598110
B17: Alpine Metal Tech
B18: Net Sales | W18: 36959 | Y18: 98060 | AA18: =Y18 -> 98060 | AB18: =AA18 -> 98060 | AC18: =AB18 -> 98060 | AD18: =AC18 -> 98060 | AE18: =AD18 -> 98060
B19: Intersegment | W19: 0 | Y19: 10 | AA19: 0 | AB19: 0 | AC19: 0 | AD19: 0 | AE19: 0
B20: Sales | W20: =W19+W18 -> 36959 | Y20: =Y19+Y18 -> 98070 | AA20: =AA19+AA18 -> 98060 | AB20: =AB19+AB18 -> 98060 | AC20: =AC19+AC18 -> 98060 | AD20: =AD19+AD18 -> 98060 | AE20: =AE19+AE18 -> 98060
B21: Net Sales Growth Y/Y | W21: =W18/V18-1 -> #DIV/0! | Y21: =Y18/W18-1 -> 1.6532103
B22: EBITDA | W22: 4042 | Y22: 9139
B23: Margin% | W23: =W22/W$20 -> 0.10936443 | Y23: =Y22/Y$20 -> 0.093188539
B24: D&A | W24: -1538 | Y24: -4054
B25: Margin% | W25: =-W24/W$7 -> 0.0018856844 | Y25: =-Y24/Y$7 -> 0.0046001688
B26: Investments | W26: 1580 | Y26: 1226
B27: Share of rev% | W27: =W26/W$7 -> 0.001937179 | Y27: =Y26/Y$7 -> 0.0013911709
B28: Valuation Multiple | Y28: 7.5
B29: Segment Value | Y29: =Y22*Y28 -> 68542.5
B30: E-Mobility
B31: Net Sales | C31: 45307 | D31: =94443-C31 -> 49136 | E31: =140817-D31-C31 -> 46374 | F31: =U31-E31-D31-C31 -> 50201 | G31: 46930 | H31: =89997-G31 -> 43067 | I31: =127413-H31-G31 -> 37416 | J31: =V31-I31-H31-G31 -> 38623 | K31: 40651 | T31: 122493 | U31: 191018 | V31: 166036
B32: Intersegment | C32: 85 | D32: =163-C32 -> 78 | E32: =0-D32-C32 -> -163 | F32: =U32-E32-D32-C32 -> 204 | G32: 224 | H32: =310-G32 -> 86 | I32: =513-H32-G32 -> 203 | J32: =V32-I32-H32-G32 -> 323 | K32: 49 | T32: 1 | U32: 204 | V32: 836
B33: Sales | C33: =C32+C31 -> 45392 | D33: =D32+D31 -> 49214 | E33: =E32+E31 -> 46211 | F33: =F32+F31 -> 50405 | G33: =G32+G31 -> 47154 | H33: =H32+H31 -> 43153 | I33: =I32+I31 -> 37619 | J33: =J32+J31 -> 38946 | K33: =K32+K31 -> 40700 | T33: =T32+T31 -> 122494 | U33: =U32+U31 -> 191222 | V33: =V32+V31 -> 166872
B34: EBITDA | C34: 4163 | D34: =8040-C34 -> 3877 | E34: =12675-D34-C34 -> 4635 | F34: =U34-E34-D34-C34 -> 11722 | G34: 3296 | H34: =7191-G34 -> 3895 | I34: =18280-H34-G34 -> 11089 | J34: =V34-I34-H34-G34 -> 7101 | K34: 1900 | T34: 8582 | U34: 24397 | V34: 25381
B35: Margin% | C35: =C34/C$7 -> 0.046318858 | D35: =D34/D$33 -> 0.078778396 | E35: =E34/E$7 -> 0.026288177 | F35: =F34/F$7 -> 0.05785642 | G35: =G34/G$7 -> 0.019764932 | H35: =H34/H$33 -> 0.090260237 | I35: =I34/I$7 -> 0.06719873 | J35: =J34/J$7 -> 0.034338853 | K35: =K34/K$33 -> 0.046683047 | T35: =T34/T$7 -> 0.030115979 | U35: =U34/U$7 -> 0.038334326 | V35: =V34/V$7 -> 0.036025487
B36: D&A | C36: -2444 | D36: =-4926-C36 -> -2482 | E36: =-7489-D36-C36 -> -2563 | F36: =U36-E36-D36-C36 -> -3025 | G36: -2535 | H36: =-5089-G36 -> -2554 | I36: =-7258-H36-G36 -> -2169 | J36: =V36-I36-H36-G36 -> -2853 | K36: -2418 | T36: -9731 | U36: -10514 | V36: -10111
B37: Margin% | C37: =-C36/C$7 -> 0.027192719 | D37: =-D36/D$33 -> 0.050432804 | E37: =-E36/E$7 -> 0.014536483 | F37: =-F36/F$7 -> 0.01493053 | G37: =-G36/G$7 -> 0.015201487 | H37: =-H36/H$33 -> 0.059184761 | I37: =-I36/I$7 -> 0.013144021 | J37: =-J36/J$7 -> 0.013796472 | K37: =-K36/K$33 -> 0.059410319 | T37: =-T36/T$7 -> 0.034148053 | U37: =-U36/U$7 -> 0.016520355 | V37: =-V36/V$7 -> 0.014351432
B38: Investments | C38: 2105 | D38: =4622-C38 -> 2517 | E38: =5174-D38-C38 -> 552 | F38: =U38-E38-D38-C38 -> 1473 | G38: 2105 | H38: =4622-G38 -> 2517 | I38: =4429-H38-G38 -> -193 | J38: =V38-I38-H38-G38 -> 1691 | K38: 11805 | T38: 5444 | U38: 6647 | V38: 6120
B39: Share of % | C39: =C38/C$7 -> 0.023420897 | D39: =D38/D$33 -> 0.051143983 | E39: =E38/E$7 -> 0.0031307603 | F39: =F38/F$7 -> 0.0072703043 | G39: =G38/G$7 -> 0.012622931 | H39: =H38/H$33 -> 0.058327347 | I39: =I38/I$7 -> -0.0011695694 | J39: =J38/J$7 -> 0.0081772989 | K39: =K38/K$33 -> 0.29004914 | T39: =T38/T$7 -> 0.019104101 | U39: =U38/U$7 -> 0.010444246 | V39: =V38/V$7 -> 0.0086866545
B40: Energy (*discontinued in Q3 2025*)
B41: Net Sales | C41: 108622 | D41: =227434-C41 -> 118812 | E41: =348609-D41-C41 -> 121175 | F41: =U41-E41-D41-C41 -> 130985 | G41: 139764 | H41: =281986-G41 -> 142222 | I41: =418024-H41-G41 -> 136038 | J41: =V41-I41-H41-G41 -> 149257 | K41: 147649 | L41: =311671-K41 -> 164022 | M41: =469420-L41-K41 -> 157749 | N41: =W41-M41-L41-K41 -> 173228 | O41: 170377 | P41: =356661-O41 -> 186284 | T41: 382972 | U41: 479594 | V41: 567281 | W41: 642648 | Y41: 525650
...

Sheet SubsidiariesAffiliates
B1: Wholly Owned | C1: p.176 of 208 in 2024 annual
B2: Company | C2: Countries | D2: Acquisition Price | E2: Multiple | F2: Description
B3: Alpine Metal Tech | C3: CN|BR|DK|DE|AT|US|UK | F3: Special purpose machinery for steel, auto, aerospace, "lifecycle business." Product line incl. NUMTEC (aluminum wheel industry deburring); GEGA (autogenous touch cutting and scarfing) KNORR (optoelectronic measuring & image processingsystems - rails); MAKRA (clamping devices & testing aluminium wheels. AMAKON (conveyors); MAGNEMAG (paints and inkjets for plate pipe and long products); SIMULATION (fire training); INTERMATO (vertical lathes - machines for machining workpieces with diameters from 100mm to 6m).
B4: Asco Aerospace | C4: CA|US|DE|BE | F4: April 2022 Acquisition. Manufacture high-lift mechanisms and critical structure sub-assemblies. Portfolio: large complex fuselage, wing and landing gear components. Partnership with Lockheed Martin (F-35)
B5: ASTA Group | C5: BA|US|CN|AT|IN
B6: GeGa GmbH
B7: Immobiliere Asco NV
B8: IMT Intermato SRL
B9: Industrie Captial Alpha GmbH
B10: Insulated Conductors and Enameled Wires NV | C10: NL
B11: MAKRA GmbH
B12: MTC Aerosystems | C12: HU| US
B13: PPE Fios Esmaitados S.A
B14: S.R.I.F. NV | C14: BE
B15: Simulation live Fire Training Solution Inc. | C15: US (Pittsburgh)
B16: Universal Alloy Corp | C16: SG|RO|VN|US (Georgia) | F16: <= gloabal manufacturer of structural components and assemblies; 4,300 headcount. Acquired by Montana Tech components
B19: Subsidiary
B20: Cefival S.A. (90% ownership; Persan FR)
B21: PT IMT Intermo Asia | C21: ID
B23: Affiliated
B24: BeLighting
B25: Belairbus NV
B26: Flabel Corporation Nv
