Workbook

Sheet Main
B1: Financials are presented in euros | D1: =C3*62526.632 -> 1328690.9 | F1: Reinach (Kanton Aargau, Schweiz)
B2: #VALUE! | D2: #VALUE! | E2: #VALUE! | F2: Engineering services/ Highly demanding aerostructures
B3: Price | C3: {=_FV(B2,"Price")} -> 21.25 | D3: {=_FV(D2,"Price")} -> 1.2575 | E3: {=_FV(E2,"Price")} -> 1.0858 | F3: Recycling & cast house (where recyclables ar emelted)
B4: Market cap CHF | C4: =C3*C5 -> 1328690.9 | F4: Extrusion (shaping metals through a shaped die)
B5: Shares outstanding | C5: =Model!AF137 -> 62526.632 | D5: =C6*D3 -> 1814186 | E5: #VALUE! | F5: Machining
B6: Market cap | C6: =C4*E3 -> 1442692.6 | E6: {=_FV(E5,"Price")} -> 1.1572 | F6: Surface Finishing (SF) Treatment & painting
B7: (-) Cash | C7: =-Model!AF169 -> -112759 | F7: Subassembly
B8: (+) Debt | C8: =Model!AF179+Model!AF187+Model!AF180+Model!AF188 -> 240879
B9: (+) Noncontrolling | C9: =Model!AF177 -> 15598
B10: (+) Pension liability | C10: =+Model!AF201+Model!AF202 -> 8625 | D10: =C12*E6 -> 1845775.2 | E10: =2300000/C12-1 -> 0.44197407
B11: Net debt | C11: =SUM(C7:C10) -> 152343 | D11: =C3*C5 -> 1328690.9
B12: TEV | C12: =C6+C11 -> 1595035.6 | F12: Alpine Metal Tech GmbH - bought 47% interest in 2022. Bought rest of the shares in 8/19/2024. Has full ownership.
B13: 2025 EBITDA | C13: =+Model!AF104 -> 161339
B14: TEV/2025EBITDA | C14: =C12/C13 -> 9.8862371 | D14: 11.6 | E14: =C13*D14 -> 1871532.4 | F14: Majority Shareholder - Dr. Michael Tojner
B15: P/E | C15: {=_FV(B2,"P/E",TRUE)} -> 708.3333 | E15: =+E14-C11 -> 1719189.4
B16: Alt P/E | C16: =C3/Model!V138 -> 25.893056 | E16: =E15/C5 -> 27.495314
B17: BV | C17: =Model!AF178 -> 997834 | D17: 29
B18: BVPS | C18: =C17/C5 -> 15.958544 | D18: =D17*C5/1000 -> 1813.2723 | F18: Investees
B19: P/BV | C19: =(C3*E3)/C18 -> 1.4458243 | F19: Alpine Metal Tech GmbH (wholly owned sub)
F20: Belairbus NV (129,000 Eur. BV on balance sheet)
B21: FCF (FY2025) | C21: =Model!AF248 -> 92752.885 | F21: Flabel Corporation NV
B22: FCFPS (FY2024) | C22: =C21/C5 -> 1.4834141 | F22: BeLighting NV
B23: P/FCF | C23: =C3/C22 -> 14.325063
B24: PPE | C24: =Model!P151 -> 650763 | F24: Seeking to divest energy segment at favorable point in market cycle
F25: 35 offers on the table - 39:00 on Q2 2025 call
F27: Aerostructures Product line: Aluminum, titanium, Composites
B28: LTM Net Sales | C28: =SUM(Model!P86:P86) -> 411868 | F28: Fuselage Floor Grid
B29: Sales ps | C29: =C28/C5 -> 6.5870812 | F29: Fuselage Stringers
C30: =C3/C29 -> 3.2260116 | F30: Seat Track
C31: FY2025 | D31: FY2026 | E31: FY2027 | F31: Engine Rings
B32: Revenue | C32: =Model!AF86 -> 979331 | D32: =Model!AL86 -> 1050000 | E32: =Model!AM86 -> 1119000 | F32: Wing Structures
B33: Y/Y Growth | D33: =D32/C32-1 -> 0.072160485 | E33: =E32/D32-1 -> 0.065714286 | F33: False Rail
B34: EBITDA | C34: =Model!AF99 -> 160592 | D34: =Model!AL104 -> 181050 | E34: =Model!AM104 -> 214669 | F34: Landing Gear (737), Engine parts (737), High Lift Mechanisms
B35: Margin | C35: =C34/C32 -> 0.16398133 | D35: =D34/D32 -> 0.17242857 | E35: =E34/E32 -> 0.19184004 | F35: Aerostructure Revenue target (FY2025): 850 Eur.
B36: Y/Y Growth | D36: =D34/C34-1 -> 0.12739115 | E36: =E34/D34-1 -> 0.18568904
B37: prsent EV/EBITDA | C37: =$C$12/C34 -> 9.9322233 | D37: =$C$12/D34 -> 8.8099178 | E37: =$C$12/E34 -> 7.4302094
B38: Implied TTM multiple | C38: 11.3 | D38: 12 | E38: 11
B39: Implied TEV | C39: =C34*C38 -> 1814689.6 | D39: =D34*D38 -> 2172600 | E39: =E34*E38 -> 2361359
B40: Discount (premium) | C40: =1-(C12/C39) -> 0.12104218
B41: Net Debt | E41: =C11 -> 152343
...

Sheet Model
O1: Un-restated. Old data. | S1: Restated | Z1: P.243 of 320 (prospectus) | AF1: P.133 of 124 | AH1: CAGR Analysis
C2: Q1'2022 | D2: Q2'2022 | E2: Q3'2022 | F2: Q4'2022 | G2: Q1'2023 | H2: Q2'2023 | I2: Q3'2023 | J2: Q4'2023 | K2: Q1'2024 | L2: Q2'2024 | M2: Q3'2024 | N2: Q4'2024 | O2: Q1'2025 | P2: Q2'2025 | Q2: Q3'2025 | S2: Q1'2025 | U2: Q1'2026 | V2: TTM Figures | X2: FY2018 | Y2: FY2019 | Z2: FY2020 | AA2: FY2021 | AB2: FY2022 | AC2: FY2023 | AD2: FY2024 | AE2: FY2024-restated | AF2: FY2025 | AH2: 22-25 | AI2: 21-25 | AJ2: 18-25 | AL2: 2026 | AM2: =AL2+1 -> 2027 | AN2: =AM2+1 -> 2028 | AO2: =AN2+1 -> 2029 | AP2: =AO2+1 -> 2030 | AQ2: =AP2+1 -> 2031 | AR2: =AQ2+1 -> 2032 | AS2: =AR2+1 -> 2033 | AT2: =AS2+1 -> 2034 | ... BM2: =BL2+1 -> 2053
B3: Stock price at 12/31 | AA3: 34 | AB3: 14.34 | AC3: 17.66 | AD3: 14.32 | AF3: 28.3 | AH3: =IFERROR(((AF3/AB3))^(1/(2025-2022))-1,"") -> 0.25433179 | AI3: =((AF3/AA3)^(1/(2025-2021)))-1 -> -0.044838344 | AJ3: =IFERROR((AF3/X3)^(1/(2025-2018))-1,"")
B4: Market cap | AA4: =+AA3*AA137 -> 1420135.2 | AB4: =+AB3*AB137 -> 871985.06 | AC4: =+AC3*AC137 -> 1094665.6 | AD4: =+AD3*AD137 -> 887929.56 | AF4: =+AF3*AF137 -> 1769503.7 | AH4: =IFERROR(((AF4/AB4))^(1/(2025-2022))-1,"") -> 0.26604014 | AJ4: =IFERROR((AF4/X4)^(1/(2025-2018))-1,"")
B5: (+) net debt | AA5: =+AA204 -> 81050 | AB5: =+AB204 -> 277963 | AC5: =+AC204 -> 273987 | AD5: =+AD204 -> 217998 | AF5: =+AF204 -> 152343 | AH5: =IFERROR(((AF5/AB5))^(1/(2025-2022))-1,"") -> -0.18163854 | AJ5: =IFERROR((AF5/X5)^(1/(2025-2018))-1,"")
B6: TEV | AA6: =+AA4+AA5 -> 1501185.2 | AB6: =+AB4+AB5 -> 1149948.1 | AC6: =+AC4+AC5 -> 1368652.6 | AD6: =+AD4+AD5 -> 1105927.6 | AF6: =+AF4+AF5 -> 1921846.7 | AH6: =IFERROR(((AF6/AB6))^(1/(2025-2022))-1,"") -> 0.18671611 | AJ6: =IFERROR((AF6/X6)^(1/(2025-2018))-1,"")
B7: TEV/EBITDA | AA7: =AA6/AA99 -> 32.596904 | AB7: =AB6/AB99 -> 9.0601309 | AC7: =AC6/AC99 -> 14.124091 | AD7: =AD6/AD99 -> 6.8918885 | AF7: =AF6/AF99 -> 11.967263 | AH7: =IFERROR(((AF7/AB7))^(1/(2025-2022))-1,"") -> 0.097202495 | AJ7: =IFERROR((AF7/X7)^(1/(2025-2018))-1,"")
A8: X | B8: SEGMENT | AH8: =IFERROR(((AF8/AB8))^(1/(2025-2022))-1,"") | AJ8: =IFERROR((AF8/X8)^(1/(2025-2018))-1,"")
B9: Aerostructures
B10: Net Sales | C10: 89358 | D10: =256935-C10 -> 167577 | E10: =433174-D10-C10 -> 176239 | F10: =AB10-E10-D10-C10 -> 202349 | G10: 166389 | H10: =332024-G10 -> 165635 | I10: =496727-H10-G10 -> 164703 | J10: =AC10-I10-H10-G10 -> 206340 | K10: 207384 | L10: =407878-K10 -> 200494 | M10: =610539-L10-K10 -> 202661 | N10: =AD10-M10-L10-K10 -> 203526 | O10: 221323 | P10: =429903-O10 -> 208580 | Q10: =649100-P10-O10 -> 219197 | S10: 221323 | U10: 233528 | V10: =Q10+P10+O10+N10 -> 852626 | AA10: 284587 | AB10: 635523 | AC10: 703067 | AD10: 814065 | AF10: 881272 | AH10: =IFERROR(((AF10/AB10))^(1/(2025-2022))-1,"") -> 0.11513188 | AI10: =((AF10/AA10)^(1/(2025-2021)))-1 -> 0.32655032 | AL10: 950000
B11: Intersegment | C11: 519 | D11: =572-C11 -> 53 | E11: =648-D11-C11 -> 76 | F11: =AB11-E11-D11-C11 -> 256 | G11: 371 | H11: =695-G11 -> 324 | I11: =1010-H11-G11 -> 315 | J11: =AC11-I11-H11-G11 -> 452 | K11: 389 | L11: =1102-K11 -> 713 | M11: =1462-L11-K11 -> 360 | N11: =AD11-M11-L11-K11 -> 92 | O11: 0 | P11: 0 | Q11: 0 | S11: 0 | U11: 0 | V11: =Q11+P11+O11+N11 -> 92 | AA11: 378 | AB11: 904 | AC11: 1462 | AD11: 1554 | AF11: 0 | AH11: =IFERROR(((AF11/AB11))^(1/(2025-2022))-1,"") -> -1 | AI11: =((AF11/AA11)^(1/(2025-2021)))-1 -> -1 | AL11: 0
B12: Sales | C12: =C11+C10 -> 89877 | D12: =D11+D10 -> 167630 | E12: =E11+E10 -> 176315 | F12: =F11+F10 -> 202605 | G12: =G11+G10 -> 166760 | H12: =H11+H10 -> 165959 | I12: =I11+I10 -> 165018 | J12: =J11+J10 -> 206792 | ... Q12: =Q11+Q10 -> 219197 | S12: =S11+S10 -> 221323 | U12: =U11+U10 -> 233528 | V12: =V11+V10 -> 852718 | AA12: =AA11+AA10 -> 284965 | AB12: =AB11+AB10 -> 636427 | AC12: =AC11+AC10 -> 704529 | AD12: =AD11+AD10 -> 815619 | AF12: =AF11+AF10 -> 881272 | AH12: =IFERROR(((AF12/AB12))^(1/(2025-2022))-1,"") -> 0.11460364 | AI12: =((AF12/AA12)^(1/(2025-2021)))-1 -> 0.32611019 | AL12: =AL11+AL10 -> 950000 | AM12: =AL12*(1+AM13) -> 1016500 | AN12: =AM12*(1+AN13) -> 1077490 | AO12: =AN12*(1+AO13) -> 1131364.5 | AP12: =AO12*(1+AP13) -> 1176619.1 | AQ12: =AP12*(1+AQ13) -> 1217800.7 | AR12: =AQ12*(1+AR13) -> 1254334.8 | AS12: =AR12*(1+AS13) -> 1279421.5 | AT12: =AS12*(1+AT13) -> 1305009.9 | AU12: =AT12*(1+AU13) -> 1331110.1
B13: Net Sales Growth Y/Y | U13: =U12/S12-1 -> 0.055145647 | V13: =V12/AD12-1 -> 0.045485699 | AB13: =AB10/AA10-1 -> 1.2331414 | AC13: =AC10/AB10-1 -> 0.10628097 | AD13: =AD10/AC10-1 -> 0.15787685 | AF13: =AF10/AD10-1 -> 0.08255729 | AH13: =IFERROR(((AF13/AB13))^(1/(2025-2022))-1,"") -> -0.59394875 | AL13: =AL12/AF12-1 -> 0.077987273 | AM13: 0.07 | AN13: 0.06 | AO13: 0.05 | AP13: 0.04 | AQ13: 0.035 | AR13: 0.03 | AS13: 0.02 | AT13: 0.02 | AU13: 0.02
B14: EBITDA | C14: 11678 | D14: =24586-C14 -> 12908 | E14: =32702-D14-C14 -> 8116 | F14: =AB14-E14-D14-C14 -> 33006 | G14: 13452 | H14: =35171-G14 -> 21719 | I14: =52695-H14-G14 -> 17524 | J14: =AC14-I14-H14-G14 -> 20874 | K14: 29287 | L14: =60097-K14 -> 30810 | M14: =90888-L14-K14 -> 30791 | N14: =AD14-M14-L14-K14 -> 36147 | O14: 39812 | P14: =76421-O14 -> 36609 | Q14: =111200-P14-O14 -> 34779 | S14: 39812 | U14: 42468 | V14: =Q14+P14+O14+N14 -> 147347 | AA14: 35127 | AB14: 65708 | AC14: 73569 | AD14: 127035 | AF14: 159811 | AH14: =IFERROR(((AF14/AB14))^(1/(2025-2022))-1,"") -> 0.34481581 | AI14: =((AF14/AA14)^(1/(2025-2021)))-1 -> 0.46046584 | AL14: =AL15*AL12 -> 171000 | AM14: =AM15*AM12 -> 203300 | AN14: =AN15*AN12 -> 210110.55 | AO14: =AO15*AO12 -> 220616.08 | AP14: =AP15*AP12 -> 229440.72 | AQ14: =AQ15*AQ12 -> 237471.15 | AR14: =AR15*AR12 -> 244595.28 | AS14: =AS15*AS12 -> 249487.19 | ... AU14: =AU15*AU12 -> 259566.47
B15: Margin% | C15: =C14/C$12 -> 0.12993313 | D15: =D14/D$12 -> 0.077002923 | E15: =E14/E$12 -> 0.046031251 | F15: =F14/F$12 -> 0.16290812 | G15: =G14/G$12 -> 0.080666827 | H15: =H14/H$12 -> 0.13086967 | I15: =I14/I$12 -> 0.10619448 | J15: =J14/J$12 -> 0.10094201 | ... Q15: =Q14/Q$12 -> 0.15866549 | S15: =S14/S$12 -> 0.17988189 | U15: =U14/U$12 -> 0.181854 | V15: =V14/V$12 -> 0.17279687 | AA15: =AA14/AA$12 -> 0.12326777 | AB15: =AB14/AB$12 -> 0.10324515 | AC15: =AC14/AC$12 -> 0.10442295 | AD15: =AD14/AD$12 -> 0.15575287 | AF15: =AF14/AF$12 -> 0.18134129 | AH15: =IFERROR(((AF15/AB15))^(1/(2025-2022))-1,"") -> 0.20654173 | AI15: =((AF15/AA15)^(1/(2025-2021)))-1 -> 0.1013156 | AL15: 0.18 | AM15: 0.2 | AN15: 0.195 | AO15: 0.195 | AP15: 0.195 | AQ15: 0.195 | AR15: 0.195 | AS15: 0.195 | AT15: 0.195 | AU15: 0.195
B16: D&A | C16: -14970 | D16: =-37801-C16 -> -22831 | E16: =-62307-D16-C16 -> -24506 | F16: =AB16-E16-D16-C16 -> -27111 | G16: -22983 | H16: =-42109-G16 -> -19126 | I16: =-64593-H16-G16 -> -22484 | J16: =AC16-I16-H16-G16 -> -17934 | K16: -20244 | L16: =-41789-K16 -> -21545 | M16: =-62487-L16-K16 -> -20698 | N16: =AD16-M16-L16-K16 -> -20512 | O16: -21520 | P16: =-42525-O16 -> -21005 | S16: -21520 | U16: -22541 | AA16: -54104 | AB16: -89418 | AC16: -82527 | AD16: -82999 | AF16: -87106 | AH16: =IFERROR(((AF16/AB16))^(1/(2025-2022))-1,"") -> -0.0086940649 | AI16: =((AF16/AA16)^(1/(2025-2021)))-1 -> 0.12643121 | AL16: =-AL17*AL12 -> -90250 | AM16: =-AM17*AM12 -> -91485 | AN16: =-AN17*AN12 -> -91586.65 | AO16: =-AO17*AO12 -> -90509.16 | AP16: =-AP17*AP12 -> -88246.431 | AQ16: =-AQ17*AQ12 -> -85246.052 | AR16: =-AR17*AR12 -> -81531.76 | AS16: =-AS17*AS12 -> -76765.288 | ... AU16: =-AU17*AU12 -> -79866.606
B17: % of revenue | C17: =-C16/C$12 -> 0.16656097 | D17: =-D16/D$12 -> 0.13619877 | E17: =-E16/E$12 -> 0.13898988 | F17: =-F16/F$12 -> 0.1338121 | G17: =-G16/G$12 -> 0.13782082 | H17: =-H16/H$12 -> 0.11524533 | I17: =-I16/I$12 -> 0.1362518 | J17: =-J16/J$12 -> 0.086724825 | ... P17: =-P16/P$12 -> 0.10070477 | S17: =-S16/S$12 -> 0.097233455 | U17: =-U16/U$12 -> 0.096523757 | AA17: =-AA16/AA$12 -> 0.18986191 | AB17: =-AB16/AB$12 -> 0.14050001 | AC17: =-AC16/AC$12 -> 0.11713783 | AD17: =-AD16/AD$12 -> 0.10176197 | AF17: =-AF16/AF$12 -> 0.09884122 | AH17: =IFERROR(((AF17/AB17))^(1/(2025-2022))-1,"") -> -0.11062023 | AI17: =((AF17/AA17)^(1/(2025-2021)))-1 -> -0.15057496 | AL17: 0.095 | AM17: 0.09 | AN17: 0.085 | AO17: 0.08 | AP17: 0.075 | AQ17: 0.07 | AR17: 0.065 | AS17: 0.06 | AT17: 0.06 | AU17: 0.06
B18: Segment EBIT | S18: =S14+S16 -> 18292 | U18: =U14+U16 -> 19927 | AA18: =AA14+AA16 -> -18977 | AB18: =AB14+AB16 -> -23710 | AC18: =AC14+AC16 -> -8958 | AD18: =AD14+AD16 -> 44036 | AF18: =AF14+AF16 -> 72705 | AH18: =IFERROR(((AF18/AB18))^(1/(2025-2022))-1,"") -> -2.452817 | AL18: =AL14+AL16 -> 80750 | AM18: =AM14+AM16 -> 111815 | AN18: =AN14+AN16 -> 118523.9 | AO18: =AO14+AO16 -> 130106.92 | AP18: =AP14+AP16 -> 141194.29 | AQ18: =AQ14+AQ16 -> 152225.09 | AR18: =AR14+AR16 -> 163063.52 | AS18: =AS14+AS16 -> 172721.9 | ... AU18: =AU14+AU16 -> 179699.86
B19: Margin% | S19: =S18/S$12 -> 0.082648437 | U19: =U18/U$12 -> 0.085330239 | AA19: =AA18/AA$12 -> -0.066594143 | AB19: =AB18/AB$12 -> -0.037254862 | AC19: =AC18/AC$12 -> -0.012714878 | AD19: =AD18/AD$12 -> 0.053990895 | AF19: =AF18/AF$12 -> 0.082500068 | AH19: =IFERROR(((AF19/AB19))^(1/(2025-2022))-1,"") -> -2.3034382 | AL19: =AL18/AL$12 -> 0.085 | AM19: =AM18/AM$12 -> 0.11 | AN19: =AN18/AN$12 -> 0.11 | AO19: =AO18/AO$12 -> 0.115 | AP19: =AP18/AP$12 -> 0.12 | AQ19: =AQ18/AQ$12 -> 0.125 | AR19: =AR18/AR$12 -> 0.13 | AS19: =AS18/AS$12 -> 0.135 | ... AU19: =AU18/AU$12 -> 0.135
B20: Investments | C20: 16369 | D20: =30538-C20 -> 14169 | E20: =49043-D20-C20 -> 18505 | F20: =AB20-E20-D20-C20 -> 28179 | G20: 12492 | H20: =24312-G20 -> 11820 | I20: =34871-H20-G20 -> 10559 | J20: =AC20-I20-H20-G20 -> 19149 | K20: 11805 | L20: =25517-K20 -> 13712 | M20: =39783-L20-K20 -> 14266 | N20: =AD20-M20-L20-K20 -> 33499 | O20: 23138 | P20: =36460-O20 -> 13322 | S20: 23138 | U20: 8121 | AA20: 100787 | AB20: 77222 | AC20: 54020 | AD20: 73282 | AF20: 68161 | AH20: =IFERROR(((AF20/AB20))^(1/(2025-2022))-1,"") -> -0.04075038 | AI20: =((AF20/AA20)^(1/(2025-2021)))-1 -> -0.093155426 | AL20: =AL21*AL12 -> 66500 | AM20: =AM21*AM12 -> 71155 | AN20: =AN21*AN12 -> 75424.3 | AO20: =AO21*AO12 -> 79195.515 | AP20: =AP21*AP12 -> 82363.336 | AQ20: =AQ21*AQ12 -> 85246.052 | AR20: =AR21*AR12 -> 87803.434 | AS20: =AS21*AS12 -> 89559.503 | ... AU20: =AU21*AU12 -> 93177.706
B21: % of revenue | C21: =C20/C$12 -> 0.18212668 | D21: =D20/D$12 -> 0.084525443 | E21: =E20/E$12 -> 0.1049542 | F21: =F20/F$12 -> 0.13908344 | G21: =G20/G$12 -> 0.07491005 | H21: =H20/H$12 -> 0.07122241 | I21: =I20/I$12 -> 0.063986959 | J21: =J20/J$12 -> 0.092600294 | ... P21: =P20/P$12 -> 0.063869978 | S21: =S20/S$12 -> 0.10454404 | U21: =U20/U$12 -> 0.034775273 | AA21: =AA20/AA$12 -> 0.35368203 | AB21: =AB20/AB$12 -> 0.12133678 | AC21: =AC20/AC$12 -> 0.076675339 | AD21: =AD20/AD$12 -> 0.089848324 | AF21: =AF20/AF$12 -> 0.077343885 | AH21: =IFERROR(((AF21/AB21))^(1/(2025-2022))-1,"") -> -0.13938051 | AI21: =((AF21/AA21)^(1/(2025-2021)))-1 -> -0.31616197 | AL21: 0.07 | AM21: 0.07 | AN21: 0.07 | AO21: 0.07 | AP21: 0.07 | AQ21: 0.07 | AR21: 0.07 | AS21: 0.07 | AT21: 0.07 | AU21: 0.07
B22: Valuation Multiple | AF22: 10 | AH22: =IFERROR(((AF22/AB22))^(1/(2025-2022))-1,"")
B23: Segment Value | AF23: =AF14*AF22 -> 1598110 | AH23: =IFERROR(((AF23/AB23))^(1/(2025-2022))-1,"")
B24: Cumul. Segemnet capex | AA24: =+V20+W20+X20+Y20+AA20 -> 100787 | AB24: =+W20+X20+Y20+AA20+AB20 -> 178009 | AC24: =+X20+Y20+AA20+AB20+AC20 -> 232029 | AD24: =+Y20+AC20+AA20+AB20+AD20 -> 305311 | AF24: =+AA20+AB20+AC20+AD20+AF20 -> 373472
B25: "Cash return on segment investment" | AA25: =AA14/AA24 -> 0.34852709 | AB25: =AB14/AB24 -> 0.3691274 | AC25: =AC14/AC24 -> 0.31706813 | AD25: =AD14/AD24 -> 0.41608393 | AF25: =AF14/AF24 -> 0.42790624 | AM25: =AF10-AB10 -> 245749
B26: Δ EBIT | AB26: =AB18-AA18 -> -4733 | AC26: =AC18-AB18 -> 14752 | AD26: =AD18-AC18 -> 52994 | AF26: =AF18-AD18 -> 28669 | AL26: =AF18-AA18 -> 91682 | AM26: =AF18-AB18 -> 96415
B27: Δ Invested Capital | AB27: =AB20 -> 77222 | AC27: =AC20 -> 54020 | AD27: =AD20 -> 73282 | AF27: =AF20 -> 68161 | AL27: =AF348-AA348 -> 139349
B28: Δ EBIT/Δ Invested Capital | AB28: =AB26/AB27 -> -0.061290824 | AC28: =AC26/AC27 -> 0.27308404 | AD28: =AD26/AD27 -> 0.72315166 | AF28: =AF26/AF27 -> 0.42060709 | AL28: =AL26/AL27 -> 0.65793081
B30: Alpine Metal Tech
B31: Net Sales | O31: 17068 | S31: 17068 | U31: 14664 | AD31: 36959 | AF31: 98060 | AH31: =IFERROR(((AF31/AB31))^(1/(2025-2022))-1,"") | AL31: 100000 | AM31: =AL31 -> 100000 | AN31: =AM31 -> 100000 | AO31: =AN31 -> 100000 | AP31: =AO31 -> 100000 | AQ31: =AP31 -> 100000 | AR31: =AQ31 -> 100000 | AS31: =AR31 -> 100000 | AT31: =AS31 -> 100000 | AU31: =AT31 -> 100000
B32: Intersegment | O32: 0 | S32: 0 | U32: 0 | AD32: 0 | AF32: 10 | AH32: =IFERROR(((AF32/AB32))^(1/(2025-2022))-1,"") | AL32: 0 | AM32: 0 | AN32: 0 | AO32: 0 | AP32: 0 | AQ32: 0 | AR32: 0 | AS32: 0 | AT32: 0 | AU32: 0
B33: Sales | O33: =+O31+O32 -> 17068 | S33: =+S31+S32 -> 17068 | U33: =+U31+U32 -> 14664 | AD33: =AD32+AD31 -> 36959 | AF33: =AF32+AF31 -> 98070 | AH33: =IFERROR(((AF33/AB33))^(1/(2025-2022))-1,"") | AL33: 100000 | AM33: =AL33*(1+AM34) -> 102500 | AN33: =AM33*(1+AN34) -> 105062.5 | AO33: =AN33*(1+AO34) -> 107689.06 | AP33: =AO33*(1+AP34) -> 110381.29 | AQ33: =AP33*(1+AQ34) -> 113140.82 | AR33: =AQ33*(1+AR34) -> 115969.34 | AS33: =AR33*(1+AS34) -> 118288.73 | AT33: =AS33*(1+AT34) -> 120654.5 | AU33: =AT33*(1+AU34) -> 123067.59
B34: Net Sales Growth Y/Y | U34: =U33/S33-1 -> -0.14084837 | AD34: =AD31/AC31-1 -> #DIV/0! | AF34: N/A | AH34: =IFERROR(((AF34/AB34))^(1/(2025-2022))-1,"") | AL34: =AL33/AF33-1 -> 0.019679821 | AM34: 0.025 | AN34: 0.025 | AO34: 0.025 | AP34: 0.025 | AQ34: 0.025 | AR34: 0.025 | AS34: 0.02 | AT34: 0.02 | AU34: 0.02
B35: EBITDA | O35: 617 | S35: 617 | U35: -558 | AD35: 4042 | AF35: 9139 | AH35: =IFERROR(((AF35/AB35))^(1/(2025-2022))-1,"") | AL35: =AL33*AL36 -> 9000 | AM35: =AM33*AM36 -> 10250 | AN35: =AN33*AN36 -> 10506.25 | AO35: =AO33*AO36 -> 10768.906 | AP35: =AP33*AP36 -> 11038.129 | AQ35: =AQ33*AQ36 -> 11314.082 | AR35: =AR33*AR36 -> 11596.934 | AS35: =AS33*AS36 -> 11828.873 | ... AU35: =AU33*AU36 -> 12306.759
B36: % of revenue | O36: =O35/O33 -> 0.03614952 | S36: =S35/S33 -> 0.03614952 | U36: =U35/U33 -> -0.038052373 | AD36: =AD35/AD$33 -> 0.10936443 | AF36: =AF35/AF$33 -> 0.093188539 | AH36: =IFERROR(((AF36/AB36))^(1/(2025-2022))-1,"") | AL36: 0.09 | AM36: 0.1 | AN36: 0.1 | AO36: 0.1 | AP36: 0.1 | AQ36: 0.1 | AR36: 0.1 | AS36: 0.1 | AT36: 0.1 | AU36: 0.1
B37: D&A | O37: -1197 | S37: -1197 | U37: -1049 | AD37: -1538 | AF37: -4054 | AH37: =IFERROR(((AF37/AB37))^(1/(2025-2022))-1,"") | AL37: =-AL38*AL33 -> -4000 | AM37: =-AM38*AM33 -> -4100 | AN37: =-AN38*AN33 -> -4202.5 | AO37: =-AO38*AO33 -> -4307.5625 | AP37: =-AP38*AP33 -> -4415.2516 | AQ37: =-AQ38*AQ33 -> -4525.6329 | AR37: =-AR38*AR33 -> -4638.7737 | AS37: =-AS38*AS33 -> -4731.5491 | ... AU37: =-AU38*AU33 -> -4922.7037
B38: % of revenue | O38: =-O37/O33 -> 0.07013124 | S38: =-S37/S33 -> 0.07013124 | U38: =-U37/U33 -> 0.071535734 | AD38: =-AD37/AD$33 -> 0.04161368 | AF38: =-AF37/AF$33 -> 0.04133782 | AH38: =IFERROR(((AF38/AB38))^(1/(2025-2022))-1,"") | AL38: 0.04 | AM38: 0.04 | AN38: 0.04 | AO38: 0.04 | AP38: 0.04 | AQ38: 0.04 | AR38: 0.04 | AS38: 0.04 | AT38: 0.04 | AU38: 0.04
B39: Segment EBIT | AF39: =AF35-AF37 -> 13193
B40: Margin% | AF40: =AF39/AF33 -> 0.13452636
B41: Investments | O41: 637 | S41: 637 | U41: 553 | AD41: 1580 | AF41: 1226 | AH41: =IFERROR(((AF41/AB41))^(1/(2025-2022))-1,"") | AL41: =AL42*AL33 -> 500 | AM41: =AM42*AM33 -> 512.5 | AN41: =AN42*AN33 -> 525.3125 | AO41: =AO42*AO33 -> 538.44531 | AP41: =AP42*AP33 -> 551.90645 | AQ41: =AQ42*AQ33 -> 565.70411 | AR41: =AR42*AR33 -> 579.84671 | AS41: =AS42*AS33 -> 591.44364 | ... AU41: =AU42*AU33 -> 615.33797
...

Sheet Comps
B2: All figures are TTM and in Millions | D2: Montana Aerospace AG | F2: FACC AG | H2: FIGEAC AÉRO | J2: Ducommun (DCO) | L2: Standard Aero | M2: Senior Plc | N2: Senior PLC | P2: Montana Products | Q2: FACC AG Products
B3: Revenue | D3: =Model!AF86/1000 -> 979.331 | F3: =[1]Model!$P$82 -> 984.405 | H3: =[2]Model!$W$144 -> 486.8 | J3: =[3]Model!$C$95 -> 824.658 | L3: =[4]Model!$G$16/1000 -> 6062.513 | P3: A350 F Floor Section | Q3: Wing elements | S3: Montana & DCO
B4: EBITDA margin | D4: =Model!AF100 -> 0.16398133 | F4: =[1]Model!$P$96 -> 0.082044484 | H4: =[2]Model!$V$159 -> 0.15561305 | J4: =[3]Model!$C$108 -> 0.13183041 | L4: =[4]Model!$G$27 -> 0.12554579 | Q4: Spoilers | S4: Montana | Z4: DCO | AF4: 1/1/2022=100% | AH4: 1/1/2023=100%
B5: EBIT margin | D5: =Model!AF111 -> 0.070267356 | F5: =[1]Model!$P$93 -> 0.042995515 | H5: =[2]Model!$V$157 -> 0.051205495 | J5: =[3]Model!$C$106 -> 0.091017125 | P5: Fuselage systems | Q5: Winglets | R5: A320 | S5: Date | T5: Open | U5: High | V5: Low | W5: Close | X5: Adj Close | Y5: Volume | Z5: Open | AA5: High | AB5: Low | AC5: Close | AD5: Adj Close | AE5: Volume | AF5: AERO | AG5: DCO | AH5: AERO | AI5: DCO
B6: Unlevered Free Cash Flow | D6: =+Model!AF356/1000 -> 65.96945 | F6: =[1]Model!$P$220 -> 13.53425 | H6: =[2]Model!$V$276 -> 32.643 | J6: =[3]Model!$C$190 -> -58.396 | L6: =[4]Model!$G$131/1000 -> 234.297 | S6: 44562 | T6: 34 | U6: 36.15 | V6: 33.5 | W6: 34.9 | X6: 34.9 | Y6: 205085 | Z6: 47.44 | AA6: 49.4 | AB6: 46.9 | AC6: 46.99 | AD6: 46.99 | AE6: 113200 | AF6: =X6/$X$6 -> 1 | AG6: =AD6/$AD$6 -> 1
B7: Net Debt | D7: =Main!C11/1000 -> 152.343 | F7: =[1]Main!$C$10 -> 145.431 | H7: =[2]Main!$C$13 -> 346.833 | J7: =[3]Main!$C$10 -> 303.591 | L7: =[4]Model!$G$93 -> 0.83027626 | P7: Landing gear | Q7: Ailerons | S7: 44569 | T7: 35 | U7: 35.9 | V7: 33.55 | W7: 35.15 | X7: 35.15 | Y7: 122046 | Z7: 46.49 | AA7: 46.63 | AB7: 44.84 | AC7: 45.55 | AD7: 45.55 | AE7: 99700 | AF7: =X7/$X$6 -> 1.0071633 | AG7: =AD7/$AD$6 -> 0.96935518
B8: Net Debt to EBITDA | D8: =Model!AF206 -> 0.9486338 | F8: =[1]Model!$P$171 -> 1.8006686 | H8: =[2]Model!V221 -> 7.034764 | J8: =[3]Model!$C$154 -> 2.764108 | L8: =[4]Sheet1!$C$7/1000 -> 8163.3488 | N8: =[5]Sheet2!$C$76 -> 1.5115979 | P8: Enigne rings/nacelles | Q8: Empennage | S8: 44576 | T8: 35.05 | U8: 36.5 | V8: 33.65 | W8: 34.1 | X8: 34.1 | Y8: 96143 | Z8: 44.92 | AA8: 45.1 | AB8: 42.51 | AC8: 43.25 | AD8: 43.25 | AE8: 100000 | AF8: =X8/$X$6 -> 0.97707736 | AG8: =AD8/$AD$6 -> 0.9204086
B9: Market Cap | D9: =Main!C6/1000 -> 1442.6926 | F9: =[1]Main!$D$7 -> 739.0506 | H9: =[2]Main!$C$7 -> 509.6525 | J9: =[3]Main!$C$6 -> 2482.178 | P9: High lift mechanisms | Q9: Vertical stabilizer & rudder | S9: 44583 | T9: 34 | U9: 35.05 | V9: 31.2 | W9: 33.9 | X9: 33.9 | Y9: 153638 | Z9: 42.25 | AA9: 45.21 | AB9: 40.82 | AC9: 42.39 | AD9: 42.39 | AE9: 136000 | AF9: =X9/$X$6 -> 0.9713467 | AG9: =AD9/$AD$6 -> 0.90210683
B10: EV to 2025 EBITDA | D10: =Main!C14 -> 9.8862371 | F10: =[1]Main!$D$13 -> 10.945962 | H10: =[2]Main!$D$18 -> 11.354476 | J10: =[3]Main!$C$14 -> 22.831974 | L10: =[4]Sheet1!$C$15 -> 13.254411 | Q10: Fairings | S10: 44590 | T10: 34.1 | U10: 35.5 | V10: 33.4 | W10: 35.15 | X10: 35.15 | Y10: 84309 | Z10: 42.63 | AA10: 44.09 | AB10: 41.81 | AC10: 43.56 | AD10: 43.56 | AE10: 217100 | AF10: =X10/$X$6 -> 1.0071633 | AG10: =AD10/$AD$6 -> 0.92700575
P11: Aluminum | Q11: Radomes | S11: 44597 | T11: 35.35 | U11: 36.75 | V11: 33.1 | W11: 34.8 | X11: 34.8 | Y11: 107167 | Z11: 43.24 | AA11: 45.01 | AB11: 42.74 | AC11: 43.96 | AD11: 43.96 | AE11: 203500 | AF11: =X11/$X$6 -> 0.99713467 | AG11: =AD11/$AD$6 -> 0.9355182
S12: 44604 | T12: 34.3 | U12: 34.45 | V12: 31.5 | W12: 32 | X12: 32 | Y12: 166091 | Z12: 44.12 | AA12: 46.96 | AB12: 44.12 | AC12: 46.07 | AD12: 46.07 | AE12: 209400 | AF12: =X12/$X$6 -> 0.91690544 | AG12: =AD12/$AD$6 -> 0.98042137
B13: No. Employees | D13: 6346 | F13: 3907 | H13: 3362 | J13: 2000 | P13: Titanium | Q13: Wing to body fairings | S13: 44611 | T13: 32.15 | U13: 33.75 | V13: 24.55 | W13: 25.15 | X13: 25.15 | Y13: 303046 | Z13: 45.65 | AA13: 49.21 | AB13: 43.09 | AC13: 49.07 | AD13: 49.07 | AE13: 123900 | AF13: =X13/$X$6 -> 0.72063037 | AG13: =AD13/$AD$6 -> 1.0442647
P14: Composite | Q14: Flap track fairings | S14: 44618 | T14: 25.5 | U14: 26.1 | V14: 18.54 | W14: 18.54 | X14: 18.54 | Y14: 1211845 | Z14: 49.13 | AA14: 51.58 | AB14: 49.13 | AC14: 50.2 | AD14: 50.2 | AE14: 203900 | AF14: =X14/$X$6 -> 0.53123209 | AG14: =AD14/$AD$6 -> 1.0683124
B15: (1) defined as operating cash flow minus PPE acquisitions | J15: 1.8 | S15: 44625 | T15: 17.82 | U15: 18 | V15: 15.28 | W15: 15.9 | X15: 15.9 | Y15: 609677 | Z15: 50.57 | AA15: 52.94 | AB15: 50.22 | AC15: 50.65 | AD15: 50.65 | AE15: 168500 | AF15: =X15/$X$6 -> 0.45558739 | AG15: =AD15/$AD$6 -> 1.0778889
B16: (2) from EBITDA | S16: 44632 | T16: 15.94 | U16: 17.36 | V16: 14.84 | W16: 16.8 | X16: 16.8 | Y16: 583264 | Z16: 51.09 | AA16: 52.29 | AB16: 50.08 | AC16: 50.82 | AD16: 50.82 | AE16: 330500 | AF16: =X16/$X$6 -> 0.48137536 | AG16: =AD16/$AD$6 -> 1.0815067
S17: 44639 | T17: 17.2 | U17: 17.82 | V17: 16 | W17: 16.44 | X17: 16.44 | Y17: 262995 | Z17: 51.5 | AA17: 54.61 | AB17: 51.3 | AC17: 53.52 | AD17: 53.52 | AE17: 139800 | AF17: =X17/$X$6 -> 0.47106017 | AG17: =AD17/$AD$6 -> 1.1389657
S18: 44646 | T18: 16.34 | U18: 16.92 | V18: 15.1 | W18: 15.22 | X18: 15.22 | Y18: 525974 | Z18: 53.52 | AA18: 53.66 | AB18: 52.08 | AC18: 53.31 | AD18: 53.31 | AE18: 145600 | AF18: =X18/$X$6 -> 0.43610315 | AG18: =AD18/$AD$6 -> 1.1344967
S19: 44653 | T19: 15.52 | U19: 18.62 | V19: 15.48 | W19: 17.56 | X19: 17.56 | Y19: 646027 | Z19: 53.54 | AA19: 54.02 | AB19: 51.38 | AC19: 52.08 | AD19: 52.08 | AE19: 150900 | AF19: =X19/$X$6 -> 0.50315186 | AG19: =AD19/$AD$6 -> 1.1083209
S20: 44660 | T20: 17.66 | U20: 18.78 | V20: 17.24 | W20: 18.26 | X20: 18.26 | Y20: 302366 | Z20: 52.09 | AA20: 55.93 | AB20: 51.83 | AC20: 55.42 | AD20: 55.42 | AE20: 129700 | AF20: =X20/$X$6 -> 0.52320917 | AG20: =AD20/$AD$6 -> 1.1793999
S21: 44667 | T21: 18.26 | U21: 18.64 | V21: 17.24 | W21: 17.84 | X21: 17.84 | Y21: 522545 | Z21: 55.45 | AA21: 58.18 | AB21: 55.3 | AC21: 55.53 | AD21: 55.53 | AE21: 181300 | AF21: =X21/$X$6 -> 0.51117479 | AG21: =AD21/$AD$6 -> 1.1817408
S22: 44674 | T22: 17.5 | U22: 17.7 | V22: 14.2 | W22: 14.92 | X22: 14.92 | Y22: 658409 | Z22: 55.45 | AA22: 55.45 | AB22: 50.81 | AC22: 51.07 | AD22: 51.07 | AE22: 223100 | AF22: =X22/$X$6 -> 0.42750716 | AG22: =AD22/$AD$6 -> 1.086827
S23: 44681 | T23: 15 | U23: 16.3 | V23: 14.06 | W23: 15.6 | X23: 15.6 | Y23: 390389 | Z23: 51.3 | AA23: 55.31 | AB23: 49.14 | AC23: 50.15 | AD23: 50.15 | AE23: 265100 | AF23: =X23/$X$6 -> 0.4469914 | AG23: =AD23/$AD$6 -> 1.0672484
S24: 44688 | T24: 15.74 | U24: 16.16 | V24: 14.7 | W24: 15.58 | X24: 15.58 | Y24: 475268 | Z24: 49.34 | AA24: 49.34 | AB24: 45.03 | AC24: 46.11 | AD24: 46.11 | AE24: 229200 | AF24: =X24/$X$6 -> 0.44641834 | AG24: =AD24/$AD$6 -> 0.98127261
S25: 44695 | T25: 15.46 | U25: 16.78 | V25: 15.34 | W25: 15.5 | X25: 15.5 | Y25: 144205 | Z25: 46 | AA25: 46.31 | AB25: 40 | AC25: 40.88 | AD25: 40.88 | AE25: 241200 | AF25: =X25/$X$6 -> 0.44412607 | AG25: =AD25/$AD$6 -> 0.86997233
S26: 44702 | T26: 15.62 | U26: 15.9 | V26: 13.66 | W26: 14.94 | X26: 14.94 | Y26: 181348 | Z26: 41.66 | AA26: 44.56 | AB26: 40.69 | AC26: 44.14 | AD26: 44.14 | AE26: 144200 | AF26: =X26/$X$6 -> 0.42808023 | AG26: =AD26/$AD$6 -> 0.9393488
S27: 44709 | T27: 14.84 | U27: 17.86 | V27: 14.84 | W27: 16.84 | X27: 16.84 | Y27: 308488 | Z27: 44.11 | AA27: 46.72 | AB27: 43.78 | AC27: 45.82 | AD27: 45.82 | AE27: 207800 | AF27: =X27/$X$6 -> 0.48252149 | AG27: =AD27/$AD$6 -> 0.97510109
S28: 44716 | T28: 16.84 | U28: 17.88 | V28: 16.08 | W28: 16.3 | X28: 16.3 | Y28: 106233 | Z28: 45.95 | AA28: 47.43 | AB28: 44.64 | AC28: 46.87 | AD28: 46.87 | AE28: 212200 | AF28: =X28/$X$6 -> 0.46704871 | AG28: =AD28/$AD$6 -> 0.99744627
... S58: 44926 | T58: 14.34 | U58: 16.38 | V58: 14.34 | W58: 16.26 | X58: 16.26 | Y58: 103167 | Z58: 50.02 | AA58: 52.6 | AB58: 48.68 | AC58: 52.27 | AD58: 52.27 | AE58: 164100 | AF58: =X58/$X$6 -> 0.46590258 | AG58: =AD58/$AD$6 -> 1.1123643
S59: 44933 | T59: 16.52 | U59: 17.42 | V59: 15.8 | W59: 17.14 | X59: 17.14 | Y59: 318404 | Z59: 53.07 | AA59: 57.46 | AB59: 51.97 | AC59: 57.4 | AD59: 57.4 | AE59: 225200 | AF59: =X59/$X$6 -> 0.49111748 | AG59: =AD59/$AD$6 -> 1.2215365 | AH59: =X59/$X$59 -> 1 | AI59: =AD59/$AD$59 -> 1
S60: 44940 | T60: 17.14 | U60: 18.16 | V60: 16.52 | W60: 17.3 | X60: 17.3 | Y60: 282279 | Z60: 57.82 | AA60: 57.82 | AB60: 53.5 | AC60: 54.12 | AD60: 54.12 | AE60: 230300 | AF60: =X60/$X$6 -> 0.49570201 | AG60: =AD60/$AD$6 -> 1.1517344 | AH60: =X60/$X$59 -> 1.0093349 | AI60: =AD60/$AD$59 -> 0.94285714
S61: 44947 | T61: 17.38 | U61: 18.34 | V61: 17.04 | W61: 17.84 | X61: 17.84 | Y61: 240520 | Z61: 54.35 | AA61: 56.81 | AB61: 53.51 | AC61: 56.19 | AD61: 56.19 | AE61: 218800 | AF61: =X61/$X$6 -> 0.51117479 | AG61: =AD61/$AD$6 -> 1.1957863 | AH61: =X61/$X$59 -> 1.0408401 | AI61: =AD61/$AD$59 -> 0.97891986
S62: 44954 | T62: 17.32 | U62: 17.54 | V62: 15.84 | W62: 16.84 | X62: 16.84 | Y62: 219882 | Z62: 56.24 | AA62: 57.9 | AB62: 55.38 | AC62: 56.34 | AD62: 56.34 | AE62: 225000 | AF62: =X62/$X$6 -> 0.48252149 | AG62: =AD62/$AD$6 -> 1.1989785 | AH62: =X62/$X$59 -> 0.98249708 | AI62: =AD62/$AD$59 -> 0.9815331
S63: 44961 | T63: 16.78 | U63: 16.78 | V63: 15.4 | W63: 15.56 | X63: 15.56 | Y63: 162939 | Z63: 56.23 | AA63: 57.27 | AB63: 55.28 | AC63: 56.14 | AD63: 56.14 | AE63: 213300 | AF63: =X63/$X$6 -> 0.44584527 | AG63: =AD63/$AD$6 -> 1.1947223 | AH63: =X63/$X$59 -> 0.90781797 | AI63: =AD63/$AD$59 -> 0.97804878
S64: 44968 | T64: 15.48 | U64: 17.34 | V64: 15.42 | W64: 16.26 | X64: 16.26 | Y64: 123504 | Z64: 56.48 | AA64: 58.28 | AB64: 53.25 | AC64: 53.6 | AD64: 53.6 | AE64: 346700 | AF64: =X64/$X$6 -> 0.46590258 | AG64: =AD64/$AD$6 -> 1.1406682 | AH64: =X64/$X$59 -> 0.94865811 | AI64: =AD64/$AD$59 -> 0.93379791
S65: 44975 | T65: 16.2 | U65: 17.4 | V65: 16.12 | W65: 17 | X65: 17 | Y65: 190839 | Z65: 53.41 | AA65: 55.67 | AB65: 52.75 | AC65: 55.49 | AD65: 55.49 | AE65: 199200 | AF65: =X65/$X$6 -> 0.48710602 | AG65: =AD65/$AD$6 -> 1.1808896 | AH65: =X65/$X$59 -> 0.99183197 | AI65: =AD65/$AD$59 -> 0.96672474
S66: 44982 | T66: 17.04 | U66: 17.92 | V66: 16.94 | W66: 17.38 | X66: 17.38 | Y66: 106931 | Z66: 55.71 | AA66: 56.5 | AB66: 53.58 | AC66: 55.83 | AD66: 55.83 | AE66: 245800 | AF66: =X66/$X$6 -> 0.49799427 | AG66: =AD66/$AD$6 -> 1.1881251 | AH66: =X66/$X$59 -> 1.0140023 | AI66: =AD66/$AD$59 -> 0.97264808
S67: 44989 | T67: 17.34 | U67: 17.74 | V67: 16.24 | W67: 16.6 | X67: 16.6 | Y67: 160162 | Z67: 55.83 | AA67: 56.37 | AB67: 52.4 | AC67: 53.32 | AD67: 53.32 | AE67: 285200 | AF67: =X67/$X$6 -> 0.4756447 | AG67: =AD67/$AD$6 -> 1.1347095 | AH67: =X67/$X$59 -> 0.96849475 | AI67: =AD67/$AD$59 -> 0.92891986
S68: 44996 | T68: 16.7 | U68: 16.74 | V68: 13.92 | W68: 14.46 | X68: 14.46 | Y68: 316415 | Z68: 52.39 | AA68: 54.21 | AB68: 49.93 | AC68: 50.15 | AD68: 50.15 | AE68: 413300 | AF68: =X68/$X$6 -> 0.41432665 | AG68: =AD68/$AD$6 -> 1.0672484 | AH68: =X68/$X$59 -> 0.84364061 | AI68: =AD68/$AD$59 -> 0.87369338
S69: 45003 | T69: 14.28 | U69: 14.76 | V69: 13.26 | W69: 13.74 | X69: 13.74 | Y69: 263543 | Z69: 50.49 | AA69: 53.91 | AB69: 50.27 | AC69: 52.64 | AD69: 52.64 | AE69: 268600 | AF69: =X69/$X$6 -> 0.39369628 | AG69: =AD69/$AD$6 -> 1.1202383 | AH69: =X69/$X$59 -> 0.80163361 | AI69: =AD69/$AD$59 -> 0.91707317
S70: 45010 | T70: 13.74 | U70: 14.94 | V70: 13.38 | W70: 14.94 | X70: 14.94 | Y70: 465449 | Z70: 53.13 | AA70: 54.88 | AB70: 52.77 | AC70: 54.71 | AD70: 54.71 | AE70: 232000 | AF70: =X70/$X$6 -> 0.42808023 | AG70: =AD70/$AD$6 -> 1.1642903 | AH70: =X70/$X$59 -> 0.87164527 | AI70: =AD70/$AD$59 -> 0.95313589
...

Sheet Figure 1
B3: FACC AG
C4: FY2021 | D4: FY2022 | E4: FY2023 | F4: FY2024 | G4: FY2025 | H4: FY2026E | I4: FY2027E
B5: Aerostructures + Nacelles Segments
B6: Revenues | C6: 271.204 | D6: 332.418 | E6: 402.109 | F6: 507.733 | G6: 525.317
B7: EBITDA | C7: 7.306 | D7: -12.385 | E7: 32.507 | F7: 47.411 | G7: 53.107
B8: Margin | C8: 0.026939131 | D8: -0.037257309 | E8: 0.080841264 | F8: 0.093377819 | G8: 0.10109515
B10: Cabin Interiors Segment
B11: Revenues | C11: 497.554 | D11: 606.976 | E11: 736.202 | F11: 884.522 | G11: 984.405
B12: EBITDA | C12: 1.52 | D12: 8.824 | E12: -1.114 | F12: 2.021 | G12: 22.548
B13: Margin | C13: 0.0030549448 | D13: 0.014537642 | E13: -0.0015131717 | F13: 0.0022848499 | G13: 0.022905207
C15: 12/21 | D15: 12/22 | E15: 12/23 | F15: 12/24 | G15: 12/25 | H15: 12/26E | I15: 12/27E
B16: Montana Aerostructures Segment only
B17: Revenues | C17: 284.965 | D17: 636.427 | E17: 704.529 | F17: 815.619 | G17: 881.272 | H17: =Model!AL12/1000 -> 950 | I17: =Model!AM12/1000 -> 1016.5
B18: EBITDA | C18: 35.127 | D18: 65.708 | E18: 73.569 | F18: 127.035 | G18: 159.811 | H18: =Model!AL14/1000 -> 171 | I18: =Model!AM14/1000 -> 203.3
B19: Margin | C19: 0.12326777 | D19: 0.10324515 | E19: 0.10442295 | F19: 0.15575287 | G19: 0.18134129 | H19: =H18/H17 -> 0.18 | I19: =I18/I17 -> 0.2
B20: Group (incl. E-mobility and Energy Segments) | J20: 0.001
B21: Revenues | C21: =Model!AA86/1000 -> 790.052 | D21: =Model!AB86/1000 -> 1306.134 | E21: =Model!AC86/1000 -> 1270.348 | F21: =Model!AD86/1000 -> 1493.673 | G21: =Model!AF86/1000 -> 979.331 | H21: =(Model!AL86)*0.001 -> 1050 | I21: =(Model!AM86)*0.001 -> 1119
B22: EBITDA | C22: =Model!AA99/1000 -> 46.053 | D22: =Model!AB99/1000 -> 126.924 | E22: =Model!AC99/1000 -> 96.902 | F22: =Model!AD99/1000 -> 160.468 | G22: =Model!AF99/1000 -> 160.592 | H22: =(Model!AL99)*0.001 -> 180 | I22: =(Model!AM99)*0.001 -> 213.55
B23: Margin | C23: =C22/C21 -> 0.0582911 | D23: =D22/D21 -> 0.097175328 | E23: =E22/E21 -> 0.076279886 | F23: =F22/F21 -> 0.10743181 | G23: =G22/G21 -> 0.16398133 | H23: =H22/H21 -> 0.17142857 | I23: =I22/I21 -> 0.19084004
B24: Net Income | C24: =Model!AA133/1000 -> -49.38 | D24: =Model!AB133/1000 -> -36.775 | E24: =Model!AC133/1000 -> -38.408 | F24: =Model!AD133/1000 -> 35.787 | G24: =Model!AF133/1000 -> -3.033 | H24: =(Model!AL130)*0.001 -> 21 | I24: =(Model!AM130)*0.001 -> 22.38
B25: EPS | C25: =Model!AA138 -> -1.1733432 | D25: =Model!AB138 -> -0.59383747 | E25: =Model!AC138 -> -0.61225513 | F25: =Model!AD138 -> 0.58202194 | G25: =Model!AF138 -> -0.049115071 | H25: =Model!AL138 -> 0.33585689 | I25: =Model!AM138 -> 0.35792748
C27: 44561 | D27: =EOMONTH(C27,12) -> 44926 | E27: =EOMONTH(D27,12) -> 45291 | F27: =EOMONTH(E27,12) -> 45657 | G27: =EOMONTH(F27,12) -> 46022
B28: Sales | C28: 284965 | D28: 636427 | E28: 704529 | F28: 815619 | G28: 881272 | H28: =Model!AL12 -> 950000 | I28: =Model!AM12 -> 1016500
B29: EBITDA | C29: 35127 | D29: 65708 | E29: 73569 | F29: 127035 | G29: 159811
B30: D&A | C30: -54104 | D30: -89418 | E30: -82527 | F30: -82999 | G30: -87106
B31: Segment EBIT | C31: -18977 | D31: -23710 | E31: -8958 | F31: 44036 | G31: 72705
B32: Investments | C32: 100787 | D32: 77222 | E32: 54020 | F32: 73282 | G32: =Model!AF20 -> 68161 | H32: =Model!AL20 -> 66500 | I32: =Model!AM20 -> 71155
B33: Y/Y change
B34: Incremental revenue | D34: =D28-C28 -> 351462 | E34: =E28-D28 -> 68102 | F34: =F28-E28 -> 111090 | G34: =G28-F28 -> 65653
B35: Incremental EBITDA | D35: =D29-C29 -> 30581 | E35: =E29-D29 -> 7861 | F35: =F29-E29 -> 53466 | G35: =G29-F29 -> 32776
B36: Incremental D&A | D36: =D30-C30 -> -35314 | E36: =E30-D30 -> 6891 | F36: =F30-E30 -> -472 | G36: =G30-F30 -> -4107
B37: Incremental EBIT | D37: =D31-C31 -> -4733 | E37: =E31-D31 -> 14752 | F37: =F31-E31 -> 52994 | G37: =G31-F31 -> 28669
B38: Incremental EBIT margins | D38: =D37/D34 -> -0.013466605 | E38: =E37/E34 -> 0.21661625 | F38: =F37/F34 -> 0.47703664 | G38: =G37/G34 -> 0.43667464
B43: Y/Y change (%)
B44: =B28 -> Sales | D44: =D28/C28-1 -> 1.2333515 | E44: =E28/D28-1 -> 0.10700677 | F44: =F28/E28-1 -> 0.15767981 | G44: =G28/F28-1 -> 0.080494692
B45: =B29 -> EBITDA | D45: =D29/C29-1 -> 0.87058388 | E45: =E29/D29-1 -> 0.11963536 | F45: =F29/E29-1 -> 0.72674632 | G45: =G29/F29-1 -> 0.25800764
B46: =B30 -> D&A | D46: =D30/C30-1 -> 0.6527059 | E46: =E30/D30-1 -> -0.07706502 | F46: =F30/E30-1 -> 0.0057193403 | G46: =G30/F30-1 -> 0.049482524
B47: =B31 -> Segment EBIT | D47: =D31/C31-1 -> 0.24940718 | E47: =E31/D31-1 -> -0.62218473 | F47: =F31/E31-1 -> -5.9158294 | G47: =G31/F31-1 -> 0.65103552
B48: Sales | D48: =D32/C32-1 -> -0.23380992 | E48: =E32/D32-1 -> -0.30045842 | F48: =F32/E32-1 -> 0.35657164 | G48: =G32/F32-1 -> -0.069880735
B49: margins
...

Sheet DCF Base
V1: Critique
B2: Assumptions | F2: 2025(A) | G2: 2029E | H2: 2035E
B3: Terminal WACC | C3: 0.075 | D3: Capex/Revenue | F3: =C17/C12 -> 0.076351101 | G3: 0.076 | H3: 0.076 | U3: (a) | V3: Proof of lower risk?
B4: Terminal Growth | C4: 0.02 | D4: D&A/Revenue | F4: =-C18/C12 -> 0.093713974 | G4: 0.09 | H4: 0.07 | U4: (b) | V4: Okay with this, but please verify Boeing and Airbus numbers
B5: EUR/CHF | C5: 0.94 | D5: NWC Absorption | F5: =C20/C12 -> -0.012082738 | G5: -0.012 | H5: 0.01 | U5: (c) | V5: Proof that management can return in excess of COC?
B6: Net Debt (12/31/2025) | C6: =Main!C11/1000 -> 152.343 | D6: =C47 -> 29.120626
B7: Swiss Tax rate | C7: 0.19
B8: Terminal EBIT margin | C8: 0.12
U9: (d) | V9: Implies Montana lies in top quartile of
C10: 0 | D10: 1 | E10: 2 | F10: 3 | G10: 4 | H10: 5 | I10: 6 | J10: 7 | K10: 8 | L10: 9 | M10: 10
B11: Figures in millions | C11: 2025 | D11: 2026 | E11: =D11+1 -> 2027 | F11: =E11+1 -> 2028 | G11: =F11+1 -> 2029 | H11: =G11+1 -> 2030 | I11: =H11+1 -> 2031 | J11: =I11+1 -> 2032 | K11: =J11+1 -> 2033 | L11: =K11+1 -> 2034 | M11: =L11+1 -> 2035 | O11: Terminal | Q11: 2026-2029 | R11: 2030-2035 | S11: Aggregate | T11: CAGR
B12: Revenue | C12: =Model!$AF$86/1000 -> 979.331 | D12: =C12*(1+D13) -> 1050 | E12: =D12*(1+E13) -> 1119 | F12: =E12*(1+F13) -> 1182.5525 | G12: =F12*(1+G13) -> 1239.0536 | H12: =G12*(1+H13) -> 1287.0004 | I12: =H12*(1+I13) -> 1336.273 | J12: =I12*(1+J13) -> 1387.4321 | K12: =J12*(1+K13) -> 1440.5498 | ... M12: =L12*(1+M13) -> 1552.9639 | O12: =M12*(1+O13) -> 1584.0232 | Q12: =IFERROR(SUM(D12:G12),"") -> 4590.6061 | R12: =IFERROR(SUM(H12:M12),"") -> 8499.9203 | S12: =+SUM(D12:M12) -> 13090.526 | T12: =IFERROR(((M12/C12))^(1/(2035-2025))-1,"") -> 0.047184451
B13: Revenue growth | C13: =Model!$AF$87 -> 0.15076643 | D13: =Model!AL87 -> 0.072160485 | E13: =Model!AM87 -> 0.065714286 | F13: =Model!AN87 -> 0.056794013 | G13: =Model!AO87 -> 0.047778904 | H13: =Model!AP87 -> 0.038696315 | I13: =Model!AQ87 -> 0.038284896 | J13: =Model!AR87 -> 0.038284896 | K13: =Model!AS87 -> 0.038284896 | ... M13: =Model!AU87 -> 0.038284896 | O13: =C4 -> 0.02 | U13: (e) | V13: Must validate extended growth run rate
B14: EBIT | C14: =Model!AF110/1000 -> 68.815 | D14: =D12*D15 -> 86.8 | E14: =E12*E15 -> 119.084 | F14: =F12*F15 -> 126.0102 | G14: =G12*G15 -> 137.80731 | H14: =H12*H15 -> 149.10417 | I14: =I12*I15 -> 160.34982 | J14: =J12*J15 -> 171.40911 | K14: =K12*K15 -> 181.25977 | ... M14: =M12*M15 -> 188.63688 | O14: =O12*O15 -> 190.08278 | Q14: =IFERROR(SUM(D14:G14),"") -> 469.70152 | R14: =IFERROR(SUM(H14:M14),"") -> 1035.6711 | S14: =+SUM(D14:M14) -> 1505.3726 | T14: =IFERROR(((M14/C14))^(1/(2035-2025))-1,"") -> 0.10609989
B15: EBIT Margin | C15: =Model!$AF$111 -> 0.070267356 | D15: =Model!AL111 -> 0.082666667 | E15: =Model!AM111 -> 0.10642002 | F15: =Model!AN111 -> 0.10655781 | G15: =Model!AO111 -> 0.11121982 | H15: =Model!AP111 -> 0.11585402 | I15: =Model!AQ111 -> 0.11999779 | J15: =Model!AR111 -> 0.12354414 | K15: =Model!AS111 -> 0.1258268 | ... M15: =Model!AU111 -> 0.12146894 | O15: =C8 -> 0.12 | Q15: =Q14/Q12 -> 0.10231798 | R15: =R14/R12 -> 0.1218448 | S15: =S14/S12 -> 0.1149971 | V15: See (d)
B16: NOPAT | C16: =C14*(1-$C$7) -> 55.74015 | D16: =D14*(1-$C$7) -> 70.308 | E16: =E14*(1-$C$7) -> 96.45804 | F16: =F14*(1-$C$7) -> 102.06826 | G16: =G14*(1-$C$7) -> 111.62392 | H16: =H14*(1-$C$7) -> 120.77438 | I16: =I14*(1-$C$7) -> 129.88335 | J16: =J14*(1-$C$7) -> 138.84138 | ... M16: =M14*(1-$C$7) -> 152.79587 | O16: =O14*(1-$C$7) -> 153.96705 | Q16: =IFERROR(SUM(D16:G16),"") -> 380.45823 | R16: =IFERROR(SUM(H16:M16),"") -> 838.89356 | S16: =+SUM(D16:M16) -> 1219.3518 | T16: =IFERROR(((M16/C16))^(1/(2035-2025))-1,"") -> 0.10609989
B17: Gross Capex | C17: =Model!AF367 -> 74.773 | D17: =$C$17+($G$17-$C$17)*((D$11-$C$11)/($G$11-$C$11)) -> 79.621768 | E17: =$C$17+($G$17-$C$17)*((E$11-$C$11)/($G$11-$C$11)) -> 84.470535 | F17: =$C$17+($G$17-$C$17)*((F$11-$C$11)/($G$11-$C$11)) -> 89.319303 | G17: =G12*$G$3 -> 94.168071 | H17: =$G$17+(($M$17-$G$17)*(H$11-$G$11)/($M$11-$G$11)) -> 98.144268 | I17: =$G$17+(($M$17-$G$17)*(I$11-$G$11)/($M$11-$G$11)) -> 102.12047 | J17: =$G$17+(($M$17-$G$17)*(J$11-$G$11)/($M$11-$G$11)) -> 106.09666 | K17: =$G$17+(($M$17-$G$17)*(K$11-$G$11)/($M$11-$G$11)) -> 110.07286 | L17: =$G$17+(($M$17-$G$17)*(L$11-$G$11)/($M$11-$G$11)) -> 114.04906 | M17: =M12*$H$3 -> 118.02525 | O17: =O12*$H$3 -> 120.38576 | Q17: =IFERROR(SUM(D17:G17),"") -> 347.57968 | R17: =IFERROR(SUM(H17:M17),"") -> 648.50857 | S17: =+SUM(D17:M17) -> 996.08824 | T17: =IFERROR(((M17/C17))^(1/(2035-2025))-1,"") -> 0.046701904
B18: D&A | C18: =Model!AF368 -> -91.777 | D18: =$C$18+($G$18-$C$18)*((D$11-$C$11)/($G$11-$C$11)) -> -96.711455 | E18: =$C$18+($G$18-$C$18)*((E$11-$C$11)/($G$11-$C$11)) -> -101.64591 | F18: =$C$18+($G$18-$C$18)*((F$11-$C$11)/($G$11-$C$11)) -> -106.58037 | G18: =-G12*$G$4 -> -111.51482 | H18: =$G$18+(($M$18-$G$18)*(H$11-$G$11)/($M$11-$G$11)) -> -111.04693 | I18: =$G$18+(($M$18-$G$18)*(I$11-$G$11)/($M$11-$G$11)) -> -110.57904 | J18: =$G$18+(($M$18-$G$18)*(J$11-$G$11)/($M$11-$G$11)) -> -110.11115 | K18: =$G$18+(($M$18-$G$18)*(K$11-$G$11)/($M$11-$G$11)) -> -109.64325 | L18: =$G$18+(($M$18-$G$18)*(L$11-$G$11)/($M$11-$G$11)) -> -109.17536 | M18: =-M12*$H$4 -> -108.70747 | O18: =-O12*$H$4 -> -110.88162 | Q18: =IFERROR(SUM(D18:G18),"") -> -416.45255 | R18: =IFERROR(SUM(H18:M18),"") -> -659.2632 | S18: =+SUM(D18:M18) -> -1075.7158 | T18: =IFERROR(((M18/C18))^(1/(2035-2025))-1,"") -> 0.017074003
B19: Net Capex | C19: =C17+C18 -> -17.004 | D19: =D17+D18 -> -17.089687 | E19: =E17+E18 -> -17.175375 | F19: =F17+F18 -> -17.261062 | G19: =G17+G18 -> -17.34675 | H19: =H17+H18 -> -12.902661 | I19: =I17+I18 -> -8.4585722 | J19: =J17+J18 -> -4.0144833 | ... M19: =M17+M18 -> 9.3177832 | O19: =O17+O18 -> 9.5041389 | Q19: =IFERROR(SUM(D19:G19),"") -> -68.872875 | R19: =IFERROR(SUM(H19:M19),"") -> -10.754633 | S19: =+SUM(D19:M19) -> -79.627508 | T19: =IFERROR(((M19/C19))^(1/(2035-2025))-1,"")
B20: δ NWC | C20: =Model!AF370 -> -11.833 | D20: =$C$20+($G$20-$C$20)*((D$11-$C$11)/($G$11-$C$11)) -> -12.591911 | E20: =$C$20+($G$20-$C$20)*((E$11-$C$11)/($G$11-$C$11)) -> -13.350821 | F20: =$C$20+($G$20-$C$20)*((F$11-$C$11)/($G$11-$C$11)) -> -14.109732 | G20: =G12*$G$5 -> -14.868643 | H20: =$G$20+(($M$20-$G$20)*(H$11-$G$11)/($M$11-$G$11)) -> -9.8022625 | I20: =$G$20+(($M$20-$G$20)*(I$11-$G$11)/($M$11-$G$11)) -> -4.7358823 | J20: =$G$20+(($M$20-$G$20)*(J$11-$G$11)/($M$11-$G$11)) -> 0.330498 | K20: =$G$20+(($M$20-$G$20)*(K$11-$G$11)/($M$11-$G$11)) -> 5.3968782 | L20: =$G$20+(($M$20-$G$20)*(L$11-$G$11)/($M$11-$G$11)) -> 10.463258 | M20: =M12*$H$5 -> 15.529639 | O20: =O12*$H$5 -> 15.840232 | Q20: =IFERROR(SUM(D20:G20),"") -> -54.921107 | R20: =IFERROR(SUM(H20:M20),"") -> 17.182129 | S20: =+SUM(D20:M20) -> -37.738978 | T20: =IFERROR(((M20/C20))^(1/(2035-2025))-1,"")
B21: Reinvestment | C21: =C19+C20 -> -28.837 | D21: =D19+D20 -> -29.681598 | E21: =E19+E20 -> -30.526196 | F21: =F19+F20 -> -31.370794 | G21: =G19+G20 -> -32.215393 | H21: =H19+H20 -> -22.704924 | I21: =I19+I20 -> -13.194454 | J21: =J19+J20 -> -3.6839853 | ... M21: =M19+M20 -> 24.847422 | O21: =O19+O20 -> 25.34437 | Q21: =IFERROR(SUM(D21:G21),"") -> -123.79398 | R21: =IFERROR(SUM(H21:M21),"") -> 6.4274954 | S21: =+SUM(D21:M21) -> -117.36649 | T21: =IFERROR(((M21/C21))^(1/(2035-2025))-1,"")
B22: Reinvestment Rate | C22: =C21/C16 -> -0.51734701 | D22: =D21/D16 -> -0.4221653 | E22: =E21/E16 -> -0.31647125 | F22: =F21/F16 -> -0.30735111 | G22: =G21/G16 -> -0.28860652 | H22: =H21/H16 -> -0.18799454 | I22: =I21/I16 -> -0.10158696 | J22: =J21/J16 -> -0.02653377 | ... M22: =M21/M16 -> 0.16261841 | O22: =O21/O16 -> 0.16460905 | Q22: =Q21/Q16 -> -0.32538127 | R22: =R21/R16 -> 0.0076618724 | S22: =S21/S16 -> -0.096253179 | V22: see note (c)
B23: FCFF | C23: =C16-C21 -> 84.57715 | D23: =D16-D21 -> 99.989598 | E23: =E16-E21 -> 126.98424 | F23: =F16-F21 -> 133.43906 | G23: =G16-G21 -> 143.83932 | H23: =H16-H21 -> 143.4793 | I23: =I16-I21 -> 143.07781 | J23: =J16-J21 -> 142.52537 | ... M23: =M16-M21 -> 127.94845 | O23: =O16-O21 -> 128.62268 | Q23: =IFERROR(SUM(D23:G23),"") -> 504.25221 | R23: =IFERROR(SUM(H23:M23),"") -> 832.46606 | S23: =+SUM(D23:M23) -> 1336.7183 | T23: =IFERROR(((M23/C23))^(1/(2035-2025))-1,"") -> 0.042265108
B24: Y/Y growth | D24: =D23/C23-1 -> 0.18222946 | E24: =E23/D23-1 -> 0.26997446 | F24: =F23/E23-1 -> 0.050831681 | G24: =G23/F23-1 -> 0.077940142 | H24: =H23/G23-1 -> -0.0025029219 | I24: =I23/H23-1 -> -0.0027982701 | J24: =J23/I23-1 -> -0.0038611059 | K24: =K23/J23-1 -> -0.010745004 | ... M24: =M23/L23-1 -> -0.048294371 | O24: =O23/M23-1 -> 0.0052695245
B25: Cost of Capital | D25: 0.075 | E25: =D25 -> 0.075 | F25: =E25 -> 0.075 | G25: =F25 -> 0.075 | H25: =G25 -> 0.075 | I25: =H25-($H$25-$M$25)/5 -> 0.074 | J25: =I25-($H$25-$M$25)/5 -> 0.073 | K25: =J25-($H$25-$M$25)/5 -> 0.072 | L25: =K25-($H$25-$M$25)/5 -> 0.071 | M25: 0.07 | O25: =C3 -> 0.075
B26: Discount factor | D26: =1/((1+D25)^D10) -> 0.93023256 | E26: =1/((1+E25)^E10) -> 0.86533261 | F26: =1/((1+F25)^F10) -> 0.80496057 | G26: =1/((1+G25)^G10) -> 0.74880053 | H26: =1/((1+H25)^H10) -> 0.69655863 | I26: =1/((1+I25)^I10) -> 0.65158985 | J26: =1/((1+J25)^J10) -> 0.61066348 | K26: =1/((1+K25)^K10) -> 0.57337891 | ... M26: =1/((1+M25)^M10) -> 0.50834929
B27: PV FCFF | D27: =D23*D26 -> 93.01358 | E27: =E23*E26 -> 109.8836 | F27: =F23*F26 -> 107.41318 | G27: =G23*G26 -> 107.70696 | H27: =H23*H26 -> 99.941744 | I27: =I23*I26 -> 93.228046 | J27: =J23*J26 -> 87.035036 | K27: =K23*K26 -> 80.842947 | ... M27: =M23*M26 -> 65.042505 | O27: =O23*O26 -> 0
B28: Invested Capital | C28: =Model!AF341/1000 -> 1098.483 | D28: =C28+D21 -> 1068.8014 | E28: =D28+E21 -> 1038.2752 | F28: =E28+F21 -> 1006.9044 | G28: =F28+G21 -> 974.68902 | H28: =G28+H21 -> 951.98409 | I28: =H28+I21 -> 938.78964 | J28: =I28+J21 -> 935.10566 | K28: =J28+K21 -> 940.93214 | ... M28: =L28+M21 -> 981.11651 | O28: =M28+O21 -> 1006.4609 | Q28: =G28-D28 -> -94.112383 | R28: =M28-H28 -> 29.132419 | S28: =M28-C28 -> -117.36649 | T28: =IFERROR(((M28/C28))^(1/(2035-2025))-1,"") -> -0.011235821
B29: Incremental IC | D29: =D28-C28 -> -29.681598 | E29: =E28-D28 -> -30.526196 | F29: =F28-E28 -> -31.370794 | G29: =G28-F28 -> -32.215393 | H29: =H28-G28 -> -22.704924 | I29: =I28-H28 -> -13.194454 | J29: =J28-I28 -> -3.6839853 | K29: =K28-J28 -> 5.8264838 | ... M29: =M28-L28 -> 24.847422 | Q29: =G29-D29 -> -2.5337945 | R29: =M29-H29 -> 47.552346 | S29: =M29-D29 -> 54.52902
B30: Implied EBITDA | D30: =D14-D18 -> 183.51146 | E30: =E14-E18 -> 220.72991 | F30: =F14-F18 -> 232.59057 | G30: =G14-G18 -> 249.32214 | H30: =H14-H18 -> 260.1511 | I30: =I14-I18 -> 270.92885 | J30: =J14-J18 -> 281.52026 | K30: =K14-K18 -> 290.90303 | ... M30: =M14-M18 -> 297.34435
B31: Implied EBITDA margin | D31: =D30/D12 -> 0.17477281 | E31: =E30/E12 -> 0.1972564 | F31: =F30/F12 -> 0.19668519 | G31: =G30/G12 -> 0.20121982 | H31: =H30/H12 -> 0.20213755 | I31: =I30/I12 -> 0.20274962 | J31: =J30/J12 -> 0.20290741 | K31: =K30/K12 -> 0.20193889 | ... M31: =M30/M12 -> 0.19146894
B32: FCFF/EBITDA turnover | D32: =D23/D30 -> 0.54486843 | E32: =E23/E30 -> 0.57529238 | F32: =F23/F30 -> 0.57370795 | G32: =G23/G30 -> 0.57692157 | H32: =H23/H30 -> 0.55152295 | I32: =I23/I30 -> 0.52810103 | J32: =J23/J30 -> 0.50627037 | K32: =K23/K30 -> 0.48467674 | ... M32: =M23/M30 -> 0.43030396
B33: Sum PV (FCFF) | C33: =SUM(C27:M27) -> 916.62248
B34: Terminal cash flow | C34: =O23 -> 128.62268
B35: Terminal cost of capital | C35: =O25 -> 0.075
B36: Terminal value | C36: =C34/(C35-C4) -> 2338.5942
B37: (+) PV Terminal value | C37: =C36*M26 -> 1188.8227
B38: Sum of PV | C38: =C37+C33 -> 2105.4452
B39: Probability of failure | C39: 0.01
B40: Proceeds if firm fails | C40: =Model!$AF$178*0.5/1000 -> 498.917
...

Sheet DCF Current
V1: Critique
B2: Assumptions | F2: 2025(A) | G2: 2029E | H2: 2035E
B3: Terminal WACC | C3: 0.09 | D3: Capex/Revenue | F3: =C17/C12 -> 0.076351101 | G3: 0.07 | H3: 0.1 | U3: (a) | V3: Proof of lower risk?
B4: Terminal Growth | C4: 0.02 | D4: D&A/Revenue | F4: =-C18/C12 -> 0.093713974 | G4: 0.09 | H4: 0.07 | U4: (b) | V4: Okay with this, but please verify Boeing and Airbus numbers
B5: EUR/CHF | C5: 0.94 | D5: NWC Absorption | F5: =C20/C12 -> -0.012082738 | G5: -0.012 | H5: 0.02 | U5: (c) | V5: Proof that management can return in excess of COC?
B6: Net Debt (12/31/2025) | C6: =Main!C11/1000 -> 152.343 | D6: =C47 -> 18.353548
B7: Swiss Tax rate | C7: 0.19
B8: Terminal EBIT margin | C8: 0.12
U9: (d) | V9: Implies Montana lies in top quartile of
C10: 0 | D10: 1 | E10: 2 | F10: 3 | G10: 4 | H10: 5 | I10: 6 | J10: 7 | K10: 8 | L10: 9 | M10: 10
B11: Figures in millions | C11: 2025 | D11: 2026 | E11: =D11+1 -> 2027 | F11: =E11+1 -> 2028 | G11: =F11+1 -> 2029 | H11: =G11+1 -> 2030 | I11: =H11+1 -> 2031 | J11: =I11+1 -> 2032 | K11: =J11+1 -> 2033 | L11: =K11+1 -> 2034 | M11: =L11+1 -> 2035 | O11: Terminal | Q11: 2026-2029 | R11: 2030-2035 | S11: Aggregate | T11: CAGR
B12: Revenue | C12: =Model!$AF$86/1000 -> 979.331 | D12: =C12*(1+D13) -> 1050 | E12: =D12*(1+E13) -> 1119 | F12: =E12*(1+F13) -> 1182.5525 | G12: =F12*(1+G13) -> 1239.0536 | H12: =G12*(1+H13) -> 1287.0004 | I12: =H12*(1+I13) -> 1336.273 | J12: =I12*(1+J13) -> 1387.4321 | K12: =J12*(1+K13) -> 1440.5498 | ... M12: =L12*(1+M13) -> 1552.9639 | O12: =M12*(1+O13) -> 1584.0232 | Q12: =IFERROR(SUM(D12:G12),"") -> 4590.6061 | R12: =IFERROR(SUM(H12:M12),"") -> 8499.9203 | S12: =+SUM(D12:M12) -> 13090.526 | T12: =IFERROR(((M12/C12))^(1/(2035-2025))-1,"") -> 0.047184451
B13: Revenue growth | C13: =Model!$AF$87 -> 0.15076643 | D13: =Model!AL87 -> 0.072160485 | E13: =Model!AM87 -> 0.065714286 | F13: =Model!AN87 -> 0.056794013 | G13: =Model!AO87 -> 0.047778904 | H13: =Model!AP87 -> 0.038696315 | I13: =Model!AQ87 -> 0.038284896 | J13: =Model!AR87 -> 0.038284896 | K13: =Model!AS87 -> 0.038284896 | ... M13: =Model!AU87 -> 0.038284896 | O13: =C4 -> 0.02 | U13: (e) | V13: Must validate extended growth run rate
B14: EBIT | C14: =Model!AF110/1000 -> 68.815 | D14: =D12*D15 -> 86.8 | E14: =E12*E15 -> 119.084 | F14: =F12*F15 -> 126.0102 | G14: =G12*G15 -> 137.80731 | H14: =H12*H15 -> 149.10417 | I14: =I12*I15 -> 160.34982 | J14: =J12*J15 -> 171.40911 | K14: =K12*K15 -> 181.25977 | ... M14: =M12*M15 -> 188.63688 | O14: =O12*O15 -> 190.08278 | Q14: =IFERROR(SUM(D14:G14),"") -> 469.70152 | R14: =IFERROR(SUM(H14:M14),"") -> 1035.6711 | S14: =+SUM(D14:M14) -> 1505.3726 | T14: =IFERROR(((M14/C14))^(1/(2035-2025))-1,"") -> 0.10609989
B15: EBIT Margin | C15: =Model!$AF$111 -> 0.070267356 | D15: =Model!AL111 -> 0.082666667 | E15: =Model!AM111 -> 0.10642002 | F15: =Model!AN111 -> 0.10655781 | G15: =Model!AO111 -> 0.11121982 | H15: =Model!AP111 -> 0.11585402 | I15: =Model!AQ111 -> 0.11999779 | J15: =Model!AR111 -> 0.12354414 | K15: =Model!AS111 -> 0.1258268 | ... M15: =Model!AU111 -> 0.12146894 | O15: =C8 -> 0.12 | Q15: =Q14/Q12 -> 0.10231798 | R15: =R14/R12 -> 0.1218448 | S15: =S14/S12 -> 0.1149971 | V15: See (d)
B16: NOPAT | C16: =C14*(1-$C$7) -> 55.74015 | D16: =D14*(1-$C$7) -> 70.308 | E16: =E14*(1-$C$7) -> 96.45804 | F16: =F14*(1-$C$7) -> 102.06826 | G16: =G14*(1-$C$7) -> 111.62392 | H16: =H14*(1-$C$7) -> 120.77438 | I16: =I14*(1-$C$7) -> 129.88335 | J16: =J14*(1-$C$7) -> 138.84138 | ... M16: =M14*(1-$C$7) -> 152.79587 | O16: =O14*(1-$C$7) -> 153.96705 | Q16: =IFERROR(SUM(D16:G16),"") -> 380.45823 | R16: =IFERROR(SUM(H16:M16),"") -> 838.89356 | S16: =+SUM(D16:M16) -> 1219.3518 | T16: =IFERROR(((M16/C16))^(1/(2035-2025))-1,"") -> 0.10609989
B17: Gross Capex | C17: =Model!AF367 -> 74.773 | D17: =$C$17+($G$17-$C$17)*((D$11-$C$11)/($G$11-$C$11)) -> 77.763187 | E17: =$C$17+($G$17-$C$17)*((E$11-$C$11)/($G$11-$C$11)) -> 80.753375 | F17: =$C$17+($G$17-$C$17)*((F$11-$C$11)/($G$11-$C$11)) -> 83.743562 | G17: =G12*$G$3 -> 86.733749 | H17: =$G$17+(($M$17-$G$17)*(H$11-$G$11)/($M$11-$G$11)) -> 98.160856 | I17: =$G$17+(($M$17-$G$17)*(I$11-$G$11)/($M$11-$G$11)) -> 109.58796 | J17: =$G$17+(($M$17-$G$17)*(J$11-$G$11)/($M$11-$G$11)) -> 121.01507 | K17: =$G$17+(($M$17-$G$17)*(K$11-$G$11)/($M$11-$G$11)) -> 132.44217 | L17: =$G$17+(($M$17-$G$17)*(L$11-$G$11)/($M$11-$G$11)) -> 143.86928 | M17: =M12*$H$3 -> 155.29639 | O17: =O12*$H$3 -> 158.40232 | Q17: =IFERROR(SUM(D17:G17),"") -> 328.99387 | R17: =IFERROR(SUM(H17:M17),"") -> 760.37173 | S17: =+SUM(D17:M17) -> 1089.3656 | T17: =IFERROR(((M17/C17))^(1/(2035-2025))-1,"") -> 0.075825056
B18: D&A | C18: =Model!AF368 -> -91.777 | D18: =$C$18+($G$18-$C$18)*((D$11-$C$11)/($G$11-$C$11)) -> -96.711455 | E18: =$C$18+($G$18-$C$18)*((E$11-$C$11)/($G$11-$C$11)) -> -101.64591 | F18: =$C$18+($G$18-$C$18)*((F$11-$C$11)/($G$11-$C$11)) -> -106.58037 | G18: =-G12*$G$4 -> -111.51482 | H18: =$G$18+(($M$18-$G$18)*(H$11-$G$11)/($M$11-$G$11)) -> -111.04693 | I18: =$G$18+(($M$18-$G$18)*(I$11-$G$11)/($M$11-$G$11)) -> -110.57904 | J18: =$G$18+(($M$18-$G$18)*(J$11-$G$11)/($M$11-$G$11)) -> -110.11115 | K18: =$G$18+(($M$18-$G$18)*(K$11-$G$11)/($M$11-$G$11)) -> -109.64325 | L18: =$G$18+(($M$18-$G$18)*(L$11-$G$11)/($M$11-$G$11)) -> -109.17536 | M18: =-M12*$H$4 -> -108.70747 | O18: =-O12*$H$4 -> -110.88162 | Q18: =IFERROR(SUM(D18:G18),"") -> -416.45255 | R18: =IFERROR(SUM(H18:M18),"") -> -659.2632 | S18: =+SUM(D18:M18) -> -1075.7158 | T18: =IFERROR(((M18/C18))^(1/(2035-2025))-1,"") -> 0.017074003
B19: Net Capex | C19: =C17+C18 -> -17.004 | D19: =D17+D18 -> -18.948268 | E19: =E17+E18 -> -20.892536 | F19: =F17+F18 -> -22.836803 | G19: =G17+G18 -> -24.781071 | H19: =H17+H18 -> -12.886073 | I19: =I17+I18 -> -0.99107542 | J19: =J17+J18 -> 10.903922 | ... M19: =M17+M18 -> 46.588916 | O19: =O17+O18 -> 47.520695 | Q19: =IFERROR(SUM(D19:G19),"") -> -87.458678 | R19: =IFERROR(SUM(H19:M19),"") -> 101.10853 | S19: =+SUM(D19:M19) -> 13.649851 | T19: =IFERROR(((M19/C19))^(1/(2035-2025))-1,"")
B20: δ NWC | C20: =Model!AF370 -> -11.833 | D20: =$C$20+($G$20-$C$20)*((D$11-$C$11)/($G$11-$C$11)) -> -12.591911 | E20: =$C$20+($G$20-$C$20)*((E$11-$C$11)/($G$11-$C$11)) -> -13.350821 | F20: =$C$20+($G$20-$C$20)*((F$11-$C$11)/($G$11-$C$11)) -> -14.109732 | G20: =G12*$G$5 -> -14.868643 | H20: =$G$20+(($M$20-$G$20)*(H$11-$G$11)/($M$11-$G$11)) -> -7.2139894 | I20: =$G$20+(($M$20-$G$20)*(I$11-$G$11)/($M$11-$G$11)) -> 0.440664 | J20: =$G$20+(($M$20-$G$20)*(J$11-$G$11)/($M$11-$G$11)) -> 8.0953174 | K20: =$G$20+(($M$20-$G$20)*(K$11-$G$11)/($M$11-$G$11)) -> 15.749971 | L20: =$G$20+(($M$20-$G$20)*(L$11-$G$11)/($M$11-$G$11)) -> 23.404624 | M20: =M12*$H$5 -> 31.059277 | O20: =O12*$H$5 -> 31.680463 | Q20: =IFERROR(SUM(D20:G20),"") -> -54.921107 | R20: =IFERROR(SUM(H20:M20),"") -> 71.535864 | S20: =+SUM(D20:M20) -> 16.614757 | T20: =IFERROR(((M20/C20))^(1/(2035-2025))-1,"")
B21: Reinvestment | C21: =C19+C20 -> -28.837 | D21: =D19+D20 -> -31.540178 | E21: =E19+E20 -> -34.243357 | F21: =F19+F20 -> -36.946535 | G21: =G19+G20 -> -39.649714 | H21: =H19+H20 -> -20.100063 | I21: =I19+I20 -> -0.55041142 | J21: =J19+J20 -> 18.99924 | ... M21: =M19+M20 -> 77.648194 | O21: =O19+O20 -> 79.201158 | Q21: =IFERROR(SUM(D21:G21),"") -> -142.37978 | R21: =IFERROR(SUM(H21:M21),"") -> 172.64439 | S21: =+SUM(D21:M21) -> 30.264608 | T21: =IFERROR(((M21/C21))^(1/(2035-2025))-1,"")
B22: Reinvestment Rate | C22: =C21/C16 -> -0.51734701 | D22: =D21/D16 -> -0.44860014 | E22: =E21/E16 -> -0.3550078 | F22: =F21/F16 -> -0.36197868 | G22: =G21/G16 -> -0.35520803 | H22: =H21/H16 -> -0.16642655 | I22: =I21/I16 -> -0.0042377366 | J22: =J21/J16 -> 0.13684133 | ... M22: =M21/M16 -> 0.50818253 | O22: =O21/O16 -> 0.51440329 | Q22: =Q21/Q16 -> -0.37423237 | R22: =R21/R16 -> 0.20580012 | S22: =S21/S16 -> 0.024820243 | V22: see note (c)
B23: FCFF | C23: =C16-C21 -> 84.57715 | D23: =D16-D21 -> 101.84818 | E23: =E16-E21 -> 130.7014 | F23: =F16-F21 -> 139.0148 | G23: =G16-G21 -> 151.27364 | H23: =H16-H21 -> 140.87444 | I23: =I16-I21 -> 130.43376 | J23: =J16-J21 -> 119.84214 | ... M23: =M16-M21 -> 75.147681 | O23: =O16-O21 -> 74.765893 | Q23: =IFERROR(SUM(D23:G23),"") -> 522.83801 | R23: =IFERROR(SUM(H23:M23),"") -> 666.24916 | S23: =+SUM(D23:M23) -> 1189.0872 | T23: =IFERROR(((M23/C23))^(1/(2035-2025))-1,"") -> -0.011751296
B24: Y/Y growth | D24: =D23/C23-1 -> 0.20420443 | E24: =E23/D23-1 -> 0.28329636 | F24: =F23/E23-1 -> 0.063606072 | G24: =G23/F23-1 -> 0.088183701 | H24: =H23/G23-1 -> -0.068744302 | I24: =I23/H23-1 -> -0.074113346 | J24: =J23/I23-1 -> -0.081203061 | K24: =K23/J23-1 -> -0.096548824 | ... M24: =M23/L23-1 -> -0.18032291 | O24: =O23/M23-1 -> -0.0050805018
B25: Cost of Capital | D25: 0.075 | E25: =D25 -> 0.075 | F25: =E25 -> 0.075 | G25: =F25 -> 0.075 | H25: =G25 -> 0.075 | I25: =H25-($H$25-$M$25)/5 -> 0.074 | J25: =I25-($H$25-$M$25)/5 -> 0.073 | K25: =J25-($H$25-$M$25)/5 -> 0.072 | L25: =K25-($H$25-$M$25)/5 -> 0.071 | M25: 0.07 | O25: =C3 -> 0.09
B26: Discount factor | D26: =1/((1+D25)^D10) -> 0.93023256 | E26: =1/((1+E25)^E10) -> 0.86533261 | F26: =1/((1+F25)^F10) -> 0.80496057 | G26: =1/((1+G25)^G10) -> 0.74880053 | H26: =1/((1+H25)^H10) -> 0.69655863 | I26: =1/((1+I25)^I10) -> 0.65158985 | J26: =1/((1+J25)^J10) -> 0.61066348 | K26: =1/((1+K25)^K10) -> 0.57337891 | ... M26: =1/((1+M25)^M10) -> 0.50834929
B27: PV FCFF | D27: =D23*D26 -> 94.742492 | E27: =E23*E26 -> 113.10018 | F27: =F23*F26 -> 111.90143 | G27: =G23*G26 -> 113.27378 | H27: =H23*H26 -> 98.127306 | I27: =I23*I26 -> 84.989316 | J27: =J23*J26 -> 73.183219 | K27: =K23*K26 -> 62.080609 | ... M27: =M23*M26 -> 38.20127 | O27: =O23*O26 -> 0
B28: Invested Capital | C28: =Model!AF341/1000 -> 1098.483 | D28: =C28+D21 -> 1066.9428 | E28: =D28+E21 -> 1032.6995 | F28: =E28+F21 -> 995.75293 | G28: =F28+G21 -> 956.10321 | H28: =G28+H21 -> 936.00315 | I28: =H28+I21 -> 935.45274 | J28: =I28+J21 -> 954.45198 | K28: =J28+K21 -> 993.00087 | ... M28: =L28+M21 -> 1128.7476 | O28: =M28+O21 -> 1207.9488 | Q28: =G28-D28 -> -110.83961 | R28: =M28-H28 -> 192.74446 | S28: =M28-C28 -> 30.264608 | T28: =IFERROR(((M28/C28))^(1/(2035-2025))-1,"") -> 0.0027215537
B29: Incremental IC | D29: =D28-C28 -> -31.540178 | E29: =E28-D28 -> -34.243357 | F29: =F28-E28 -> -36.946535 | G29: =G28-F28 -> -39.649714 | H29: =H28-G28 -> -20.100063 | I29: =I28-H28 -> -0.55041142 | J29: =J28-I28 -> 18.99924 | K29: =K28-J28 -> 38.548891 | ... M29: =M28-L28 -> 77.648194 | Q29: =G29-D29 -> -8.1095355 | R29: =M29-H29 -> 97.748256 | S29: =M29-D29 -> 109.18837
B30: Implied EBITDA | D30: =D14-D18 -> 183.51146 | E30: =E14-E18 -> 220.72991 | F30: =F14-F18 -> 232.59057 | G30: =G14-G18 -> 249.32214 | H30: =H14-H18 -> 260.1511 | I30: =I14-I18 -> 270.92885 | J30: =J14-J18 -> 281.52026 | K30: =K14-K18 -> 290.90303 | ... M30: =M14-M18 -> 297.34435
B31: Implied EBITDA margin | D31: =D30/D12 -> 0.17477281 | E31: =E30/E12 -> 0.1972564 | F31: =F30/F12 -> 0.19668519 | G31: =G30/G12 -> 0.20121982 | H31: =H30/H12 -> 0.20213755 | I31: =I30/I12 -> 0.20274962 | J31: =J30/J12 -> 0.20290741 | K31: =K30/K12 -> 0.20193889 | ... M31: =M30/M12 -> 0.19146894
B32: FCFF/EBITDA turnover | D32: =D23/D30 -> 0.5549963 | E32: =E23/E30 -> 0.5921327 | F32: =F23/F30 -> 0.5976803 | G32: =G23/G30 -> 0.60673971 | H32: =H23/H30 -> 0.54151007 | I32: =I23/I30 -> 0.48143179 | J32: =J23/J30 -> 0.42569633 | K32: =K23/K30 -> 0.37219112 | ... M32: =M23/M30 -> 0.25272947
B33: Sum PV (FCFF) | C33: =SUM(C27:M27) -> 839.04975
B34: Terminal cash flow | C34: =O23 -> 74.765893
B35: Terminal cost of capital | C35: =O25 -> 0.09
B36: Terminal value | C36: =C34/(C35-C4) -> 1068.0842
B37: (+) PV Terminal value | C37: =C36*M26 -> 542.95984
B38: Sum of PV | C38: =C37+C33 -> 1382.0096
B39: Probability of failure | C39: 0.01
B40: Proceeds if firm fails | C40: =Model!$AF$178*0.5/1000 -> 498.917
...

Sheet DCF MKT
R1: Critique
B2: Assumptions | D2: =C43 -> 19.350265
B3: WACC | C3: 0.08 | Q3: (a) | R3: Proof of lower risk?
B4: Terminal Growth | C4: 0.025 | Q4: (b) | R4: Okay with this, but please verify Boeing and Airbus numbers
