Workbook

Sheet Tabelle1
B1: Date updated: | C1: 46181
B2: #VALUE! | E2: Engine Portfolio | K2: HQ: | L2: Dachauer Str. 665 80995 München Germany | R2: Military Applications
B3: Price: | C3: {=_FV(B2,"Price")} -> 328.6 | E3: Engine | F3: Manufacturer | G3: Application | H3: Thrust category (IBF) | I3: EIS | J3: MTU Service | R3: Eurofighter - EJ200 engines. 160 orders from spain and Germany. Fighter engine - key revenue driver
B4: 52w High: | C4: {=_FV(B2,"52 week high",TRUE)} -> 402.7 | E4: CF6 | F4: GE | G4: A300|747|C-5M | H4: 41,500-69,800 IBF | I4: 1971 | J4: Turbine & compressor parts | L4: Lease engines? | R4: A400- 178 in order. TP400-D6 engines. Good for aftermarket
B5: 52w Low: | C5: {=_FV(B2,"52 week low",TRUE)} -> 99.98 | E5: EJ200 | F5: JV | G5: Eurofighter Typhoon | H5: 20000 | I5: 2003 | J5: Engineering & parts for compressor. | L5: Spare parts | R5: Sikorsky Ch-53K- Germany and French orders appx. 480.
B6: Shares outstanding | C6: {=_FV(B2,"Shares outstanding",TRUE)/1000} -> 53909.16 | E6: GEnx | F6: GE | G6: 787 | H6: 66,500-76,100 | I6: 2012 | J6: Dev. Manu, assembly, repair of turbine center frame. | L6: Good if aircraft are aging? I.e., slower production lines = more business??
B7: P/E | C7: {=_FV(B2,"P/E",TRUE)} -> 17.8007 | D7: Attractive-ish | E7: GE9X | F7: GE | G7: 777X | H7: 100,000 | I7: planned | J7: dev,manu,assembly, repair of turbine center frame | R7: Commercial
B8: Market Cap | C8: {=_FV(B2,"Market cap",TRUE)/1000000} -> 20883.9 | E8: GTF (PW) | F8: PW | G8: A320 neo | A220| Embraer E-jets | I8: 2016 | J8: Manu high-speed, low pressure turbine + forward 4 stages of high pressure compressor | R8: V2500 - engine developed in 1980's. Demand for maintenance, repair, an d overhaul.
B9: (-) Cash | C9: =-Model!Y186 -> -1256 | E9: F110 | F9: GE | G9: F-16|F-15|F-15EX | H9: 29,000 | I9: 1986 | J9: Manu turbine disks for low-pressure compressor | L9: PW GTU engine: | R9: MTU has 38% market share
B10: (+) Debt | C10: =+Model!Y203+Model!Y194 -> 3230 | E10: F414 | F10: GE | G10: F/A-18 Super hornet | H10: 22,000 | I10: 1995 | J10: Parts for high and low pressure turbine | L10: In addition to being responsible for the high-speed low-pressure turbine and the first four stages of the high-pressure compressor, MTU also manufactures brush seals and nickel blisks for high-pressure compressor components that fall outside its design responsibility. Moreover, MTU in Munich is responsible for the final assembly of one-third of the production PW1100G-JM for the A320neo. | R10: Revenues from: spair parts, repairs, durability.
B11: (+) Pension | C11: =+Model!Y192+Model!Y199 -> 671 | E11: GP7000 | F11: GE/PW | G11: A380 | H11: 70,000-81,500 | I11: 2008 | J11: Various components + maintenance of low-pressure turbine | R11: PW 1000G-JM
B12: (+) Minority | C12: =+Model!Y190 -> 61 | E12: JT8D-200 | F12: PW | G12: MD-80 | H12: 18,500-21,700 | I12: 1980 | J12: Various components of various assemblies | R12: MTU has 35% market share for MRO shop visits
B13: Net Debt | C13: =C9+C10+C11+C12 -> 2706 | E13: Lazrac 04 | F13: Safran helicopter engines | G13: Dessault Alpha Jet | H13: 3,000 | I13: 1979 | J13: Hot section of engine | R13: Revenues from: MRO cost management, Repair technologies, maturing aftermarket contracts
B14: Enterprise Value | C14: =C8+C13 -> 23589.9 | E14: MTR390 | F14: MTU/RR | G14: Airbus Tiger heli | H14: 1467 shp (shaft horsepower) | I14: 2013 | J14: Manu high-pressure turbine and combustor | R14: PW LEAP-1A & LEAP-1B
B15: Equity BV | C15: =Model!Y191 -> 4375 | E15: PW300 | F15: PW | G15: Dassault Falcon | H15: 4,000-7,000 | I15: 1992 | R15: GEnx
B16: BVPS | C16: =C15/(C6/1000) -> 81.155039 | E16: PW500 | F16: PW | G16: Cessna citation/Excel/XLS | H16: 3,000-4,500 | I16: 1997 | J16: development of entire low-pressure turbine, incl. exit case and mixer | R16: GE90
B17: P/BV | C17: =C3/C16 -> 4.04904 | E17: PW800 | F17: PW | G17: Gulfstream G400/500/700| Dassault Falcon 6X | H17: 10,000-20,000 | I17: 2018 | J17: high-pressure compressor and low-pressure turbine | L17: Current backlog of Eur. 25B largely driven by PW GTF engine family (PW 1100G-JM) and V2500
E18: PW2000 | F18: PW | G18: 757|C-17 | H18: 37,500-43,000 | I18: 1984 | J18: high-pressure compressor and low-pressure turbine | L18: Received orders of $1.75 B at June 25 Paris Air Show
B19: EBITDA | C19: =Model!Y101 -> 1442 | E19: PW4000 | F19: PW | G19: 777-200(ER) & -300 | H19: 74,000-98,000 | I19: 1995 | J19: high-pressure compressor and low-pressure turbine
B20: TEV/2025 EBITDA | C20: =C14/C19 -> 16.359154 | E20: RB199 | F20: RR/MTU | G20: Panavia Tornado | H20: 16,000-17,000 | I20: 1979 | J20: Manu. Intermediate pressure and high-pressure compressor + intermediate pressure turbine
E21: T408 | F21: MTU/FiatAvio | G21: Sikorsky CH-53K | H21: 7,510 shp | I21: 2019 | J21: The power turbine
B22: OEM Segment | E22: T64 | F22: GE | G22: Sikorsky CH-53G/GS/GA/GE | H22: 4,330 shp | I22: 1972 | J22: Maintenance
B23: 5-yr avg EBITDA AVG | C23: =AVERAGE(Model!U19:Y19) -> 0.38599457 | E23: TP400-D6 | F23: RR/Safran/MTU | G23: A400M | H23: 11,000 shp | I23: 2013 | J23: Joint venture with RR and Safran
B24: TTM EBITDA | C24: =Model!Y18 -> 1141 | E24: V2500 | F24: PW/PAWEI/Japanese aero engines | G24: Airbus A319/320/321|MD-90| Embraer C-390 | H24: 22,000-33,000 | I24: 1989
B25: TEV/EBITDA Valuation multiple | C25: 15
B26: Implied Valuation | C26: =C24*C25 -> 17115 | E26: CEO | F26: Dr. Johannes Bussmann
B27: % of SOTP | C27: =C26/C$35 -> 0.7397882 | E27: CFO | F27: katja Garcia Vila
B29: MRO Segment | E29: No. employees | F29: 2025 | G29: 2024
B30: 5-yr avg EBITDA AVG | C30: =AVERAGE(Model!Y51,Model!X51,Model!W51,Model!V51) -> 0.06338443 | F30: 13345 | G30: 12508
B31: TTM EBITDA | C31: =Model!Y50 -> 301
B32: TEV/EBITDA Valuation multiple | C32: 20
B33: Implied Valuation | C33: =C31*C32 -> 6020
B34: % of SOTP | C34: =C33/C$35 -> 0.2602118
B35: SOTP Valuation | C35: =C26+C33 -> 23135
B36: Difference from actual | C36: =C35/C14 -> 0.98071632

Sheet Model
K1: 6Mo. Figures | P1: BS Restated:
C2: Q1'2024 | D2: Q2'2024 | E2: Q1'2025 | F2: Q2'2025 | G2: Q1'2026 | I2: 1H2022 | J2: 1H2023 | K2: 1H2024 | L2: 2H2024 | M2: 1H2025 | O2: =EOMONTH(P2,-12) -> 42369 | P2: =EOMONTH(Q2,-12) -> 42735 | Q2: =EOMONTH(R2,-12) -> 43100 | R2: =EOMONTH(S2,-12) -> 43465 | S2: =EOMONTH(T2,-12) -> 43830 | T2: =EOMONTH(U2,-12) -> 44196 | U2: =EOMONTH(V2,-12) -> 44561 | V2: 44926 | W2: 45291 | X2: 45657 | Y2: FY2025 | Z2: CAGR
B3: Year end stock price | M3: =Tabelle1!C3 -> 328.6 | O3: 90.1 | P3: 109.8 | Q3: 149.4 | R3: 158.4 | S3: 254.6 | T3: 213.4 | U3: 179.4 | V3: 202.2 | W3: 195.25 | X3: 322 | Y3: 355.3
A4: P.235 | B4: Segment information - OEM
A5: P.228 for cons. | B5: Commercial engine business | C5: 433 | D5: 470 | E5: 507 | F5: =M5-E5 -> 734 | G5: 479 | I5: 596 | J5: 832 | K5: 807 | L5: =X5-K5 -> 917 | M5: 1241 | O5: 2414 | P5: 2401.2 | Q5: 1289.9 | R5: 1602.8 | S5: 1537 | T5: 1052 | U5: 1066 | V5: 1335 | W5: 668 | X5: 1724 | Y5: 2178
B6: Military engine business | C6: 124 | D6: 148 | E6: 113 | F6: =M6-E6 -> 147 | G6: 142 | I6: 213 | J6: 229 | K6: 272 | L6: =X6-K6 -> 340 | M6: 260 | O6: 483.1 | P6: 504 | Q6: 444.9 | R6: 431.1 | S6: 459 | T6: 483 | U6: 482 | V6: 496 | W6: 538 | X6: 612 | Y6: 614
B7: other revenue | C7: 0 | D7: 0 | E7: 0 | F7: =M7-E7 -> -33 | I7: 0 | J7: 0 | K7: 56 | L7: =X7-K7 -> 62 | M7: -33 | O7: 0 | P7: 0 | Q7: 0 | R7: 0 | S7: 0 | T7: 0 | U7: 0 | V7: 0 | W7: 44 | X7: 118 | Y7: 129
A8: X | B8: Commercial & military (OEM segment) | C8: =SUM(C5:C7) -> 557 | D8: =SUM(D5:D7) -> 618 | E8: =SUM(E5:E7) -> 620 | F8: =SUM(F5:F7) -> 848 | G8: =SUM(G5:G7) -> 621 | I8: =SUM(I5:I7) -> 809 | J8: =SUM(J5:J7) -> 1061 | K8: =SUM(K5:K7) -> 1135 | L8: =SUM(L5:L7) -> 1319 | M8: =SUM(M5:M7) -> 1468 | O8: =SUM(O5:O7) -> 2897.1 | P8: =SUM(P5:P7) -> 2905.2 | Q8: =SUM(Q5:Q7) -> 1734.8 | R8: =SUM(R5:R7) -> 2033.9 | S8: =SUM(S5:S7) -> 1996 | T8: =SUM(T5:T7) -> 1535 | U8: =SUM(U5:U7) -> 1548 | V8: =SUM(V5:V7) -> 1831 | ... Y8: =SUM(Y5:Y7) -> 2921 | Z8: =(X8/O8)^(1/(2024-2015))-1 -> -0.018274393
B9: Y/Y growth | P9: =P8/O8-1 -> 0.0027958993 | Q9: =Q8/P8-1 -> -0.40286383 | R9: =R8/Q8-1 -> 0.17241181 | S9: =S8/R8-1 -> -0.018634151 | T9: =T8/S8-1 -> -0.23096192 | U9: =U8/T8-1 -> 0.0084690554 | V9: =V8/U8-1 -> 0.18281654 | W9: =W8/V8-1 -> -0.31731294 | ... Y9: =Y8/X8-1 -> 0.19030155
B10: Adjusted revenue | I10: 809 | J10: 1061 | K10: 1176 | L10: =X10-K10 -> 1355 | M10: 1411 | O10: 2897.1 | P10: 2905.2 | Q10: 1734.8 | R10: 2033.9 | S10: 1996 | T10: 1535 | U10: 1548 | V10: 1831 | W10: 2212 | X10: 2531 | Y10: 2875
B11: Gross profit | I11: 182 | J11: 348 | K11: 358 | L11: =X11-K11 -> 387 | M11: 571 | O11: 378.9 | P11: 422.6 | Q11: 470 | R11: 549.1 | S11: 615 | T11: 286 | U11: 351 | V11: 500 | W11: 266 | X11: 745 | Y11: 1164
B12: margin% | I12: =I11/I$8 -> 0.2249691 | J12: =J11/J$8 -> 0.32799246 | K12: =K11/K$8 -> 0.3154185 | L12: =L11/L$8 -> 0.29340409 | M12: =M11/M$8 -> 0.38896458 | O12: =O11/O$8 -> 0.13078596 | P12: =P11/P$8 -> 0.14546331 | Q12: =Q11/Q$8 -> 0.2709246 | R12: =R11/R$8 -> 0.26997394 | S12: =S11/S$8 -> 0.30811623 | T12: =T11/T$8 -> 0.18631922 | U12: =U11/U$8 -> 0.22674419 | V12: =V11/V$8 -> 0.27307482 | ... Y12: =Y11/Y$8 -> 0.39849367 | Z12: =(X12/O12)^(1/(2024-2015))-1 -> 0.098084147
B13: Amortization of intangibles | I13: -21 | J13: -24 | K13: -26 | L13: =X13-K13 -> -29 | M13: -28 | O13: -59.7 | P13: fina | Q13: -29.1 | R13: -31 | S13: -37 | T13: -39 | U13: -41 | V13: -45 | W13: -50 | X13: -55 | Y13: -58
B14: Depreciation of PPE | C14: -54 | D14: =K14-C14 -> -6 | E14: -58 | F14: =M14-E14 -> -7 | I14: -56 | J14: -56 | K14: -60 | L14: =X14-K14 -> -66 | M14: -65 | O14: -74.5 | P14: -76.2 | Q14: -47.3 | R14: -49 | S14: -53 | T14: -102 | U14: -46 | V14: -47 | W14: -115 | X14: -126 | Y14: -132
B15: Non-cash amortization of program assets | I15: -24 | J15: -23 | K15: -25 | L15: =X15-K15 -> -100 | M15: -25 | O15: 0 | P15: 0 | Q15: -79.7 | R15: -82 | S15: -93 | T15: -51 | U15: -115 | V15: -113 | W15: -50 | X15: -125 | Y15: -49
B16: Impairment losses | I16: -65 | J16: 0 | K16: 0 | L16: =X16-K16 -> -31 | M16: 0 | O16: 0 | P16: 0 | Q16: 0 | R16: 0 | S16: 0 | T16: -71 | U16: -83 | V16: -65 | W16: 0 | X16: -31 | Y16: 0
B17: D&A/adjustments/impairments | I17: =I16+I15+I14+I13 -> -166 | J17: =J16+J15+J14+J13 -> -103 | K17: =K16+K15+K14+K13 -> -111 | L17: =L16+L15+L14+L13 -> -226 | M17: =M16+M15+M14+M13 -> -118 | O17: =O16+O15+O14+O13 -> -134.2 | P17: =P16+P15+P14+P13 -> #VALUE! | Q17: =Q16+Q15+Q14+Q13 -> -156.1 | R17: =R16+R15+R14+R13 -> -162 | S17: =S16+S15+S14+S13 -> -183 | T17: =T16+T15+T14+T13 -> -263 | U17: =U16+U15+U14+U13 -> -285 | V17: =V16+V15+V14+V13 -> -270 | ... Y17: =Y16+Y15+Y14+Y13 -> -239
B18: Segment-level EBITDA | Q18: =Q22-Q17 -> 385.4 | R18: =R22-R17 -> 544.6 | S18: =S22-S17 -> 630 | T18: =T22-T17 -> 400 | U18: =U22-U17 -> 494 | V18: =V22-V17 -> 538 | W18: =W22-W17 -> 723 | X18: =X22-X17 -> 854 | Y18: =Y22-Y17 -> 1141 | Z18: =(Y18/U18)^(1/(2024-2015))-1 -> 0.097476957
B19: margin% | Q19: =Q18/Q$8 -> 0.22215817 | R19: =R18/R$8 -> 0.26776144 | S19: =S18/S$8 -> 0.31563126 | T19: =T18/T$8 -> 0.26058632 | U19: =U18/U$8 -> 0.31912145 | V19: =V18/V$8 -> 0.29382851 | W19: =W18/W$8 -> 0.5784 | X19: =X18/X$8 -> 0.34800326 | Y19: =Y18/Y$8 -> 0.39061965
B20: Valuation multiple | X20: 10 | Y20: 10
Y21: =Y18*Y20 -> 11410
B22: EBIT | C22: 130 | D22: =K22-C22 -> 108 | E22: 176 | F22: =M22-E22 -> 286 | G22: 188 | I22: 67 | J22: 223 | K22: 238 | L22: =X22-K22 -> 279 | M22: 462 | O22: 232.8 | P22: 273.7 | Q22: 229.3 | R22: 382.6 | S22: 447 | T22: 137 | U22: 209 | V22: 268 | W22: 508 | X22: 517 | Y22: 902
B23: margin% | C23: =C22/C$8 -> 0.23339318 | D23: =D22/D$8 -> 0.17475728 | E23: =E22/E$8 -> 0.28387097 | F23: =F22/F$8 -> 0.33726415 | G23: =G22/G$8 -> 0.30273752 | I23: =I22/I$8 -> 0.082818294 | J23: =J22/J$8 -> 0.21017908 | K23: =K22/K$8 -> 0.20969163 | L23: =L22/L$8 -> 0.21152388 | M23: =M22/M$8 -> 0.3147139 | O23: =O22/O$8 -> 0.080356218 | P23: =P22/P$8 -> 0.094210381 | Q23: =Q22/Q$8 -> 0.13217662 | R23: =R22/R$8 -> 0.18811151 | S23: =S22/S$8 -> 0.2239479 | T23: =T22/T$8 -> 0.089250814 | U23: =U22/U$8 -> 0.13501292 | V23: =V22/V$8 -> 0.1463681 | ... Y23: =Y22/Y$8 -> 0.30879836
B24: Special items | I24: =9+12+53+24 -> 98 | J24: =9+11+19 -> 39 | O24: =21.6+30.6 -> 52.2 | P24: =18.7+29.1 -> 47.8 | Q24: =18.6+30.2 -> 48.8 | R24: =18.6+30.2 -> 48.8 | S24: =19+30 -> 49 | T24: =18+27+24+73 -> 142 | U24: =18+23-13+83 -> 111 | V24: =18+23+53+24 -> 118 | W24: =18+23+932+23 -> 996 | X24: =18+25+52 -> 95 | Y24: =18+26-73 -> -29
B25: Adjusted EBIT | C25: 130 | D25: 252 | E25: 176 | F25: 357 | I25: =I22+I24 -> 165 | J25: =J22+J24 -> 262 | K25: 288 | L25: =X25-K25 -> 324 | M25: 415 | O25: =O22+O24 -> 285 | P25: =P22+P24 -> 321.5 | Q25: =Q22+Q24 -> 278.1 | R25: =R22+R24 -> 431.4 | S25: =S22+S24 -> 496 | T25: =T22+T24 -> 279 | U25: =U22+U24 -> 320 | V25: =V22+V24 -> 386 | ... Y25: =Y22+Y24 -> 873
B26: Profit/loss of companies accounted for using equity meth. | I26: 4 | J26: 9 | K26: 12 | L26: =X26-K26 -> 28 | M26: 38 | O26: -2.4 | P26: 1.1 | Q26: 5.3 | R26: 11.4 | S26: 30 | T26: 35 | U26: 44 | V26: 9 | W26: 27 | X26: 40 | Y26: 51
B27: Carrying amount of companeis accounted for using the equity meth | I27: 311 | J27: 307 | K27: 342 | L27: =X27-K27 -> 0 | M27: 311 | O27: 27.6 | P27: 55.8 | Q27: 137.9 | R27: 250.6 | S27: 325 | T27: 323 | U27: 339 | V27: 311 | W27: 305 | X27: 342 | Y27: 292
B28: Assets | I28: 7793 | J28: 7798 | K28: 10684 | L28: =X28-K28 -> 0 | M28: 9846 | O28: 4589.5 | P28: 5115.6 | Q28: 5434.4 | R28: 6034.5 | S28: 6687 | T28: 6996 | U28: 7189 | V28: 7793 | W28: 8802 | X28: 10684 | Y28: 10686
B29: Liabilities | I29: 5242 | J29: 5177 | K29: 7885 | L29: =X29-K29 -> 0 | M29: 6670 | O29: 3429.4 | P29: 3758.8 | Q29: 3795.6 | R29: 4118.2 | S29: 4550 | T29: 4698 | U29: 4729 | V29: 5247 | W29: 6375 | X29: 7885 | Y29: 7021
B30: Material other non-cash items | I30: 16 | J30: -5 | K30: 19 | L30: =X30-K30 -> 15 | M30: -82 | O30: 76.4 | P30: 33.7 | Q30: -35.9 | R30: 41.4 | S30: 34 | T30: -11 | U30: 36 | V30: 8 | W30: 2 | X30: 34 | Y30: -89
B31: CapEx: | L31: =X31-K31 -> 0
B32: Intangible assets | I32: 27 | J32: 28 | K32: 36 | L32: =X32-K32 -> -119 | M32: 38 | O32: -160.9 | P32: -114.3 | Q32: -68.5 | R32: -71.8 | S32: -78 | T32: -42 | U32: -54 | V32: -58 | W32: -78 | X32: -83 | Y32: -85
B33: PPE | I33: 41 | J33: 101 | K33: 122 | L33: =X33-K33 -> -385 | M33: 67 | O33: -102.9 | P33: -112.1 | Q33: -116.4 | R33: -127.5 | S33: -209 | T33: -160 | U33: -148 | V33: -157 | W33: -218 | X33: -263 | Y33: -193
B34: Acquired program assets, dev work, and other assets | I34: 24 | J34: 21 | K34: 47 | L34: =X34-K34 -> -100 | M34: 37 | O34: 0 | P34: 0 | Q34: -45.5 | R34: -59.5 | S34: -16 | T34: -12 | U34: -18 | V34: -26 | W34: -2 | X34: -53 | Y34: -38
B35: Total CAPEX | I35: =I32+I33+I34 -> 92 | J35: =J32+J33+J34 -> 150 | K35: =K32+K33+K34 -> 205 | L35: =L32+L33+L34 -> -604 | M35: =M32+M33+M34 -> 142 | O35: =O32+O33+O34 -> -263.8 | P35: =P32+P33+P34 -> -226.4 | Q35: =Q32+Q33+Q34 -> -230.4 | R35: =R32+R33+R34 -> -258.8 | S35: =S32+S33+S34 -> -303 | T35: =T32+T33+T34 -> -214 | U35: =U32+U33+U34 -> -220 | V35: =V32+V33+V34 -> -241 | ... Y35: =Y32+Y33+Y34 -> -316
B36: Perecent of revenue | I36: =I35/I$8 -> 0.11372064 | J36: =J35/J$8 -> 0.14137606 | K36: =K35/K$8 -> 0.18061674 | L36: =L35/L$8 -> -0.45792267 | M36: =M35/M$8 -> 0.096730245 | O36: =-O35/O$8 -> 0.091056574 | P36: =-P35/P$8 -> 0.07792923 | Q36: =-Q35/Q$8 -> 0.1328107 | R36: =-R35/R$8 -> 0.12724323 | S36: =-S35/S$8 -> 0.15180361 | T36: =-T35/T$8 -> 0.13941368 | U36: =-U35/U$8 -> 0.14211886 | V36: =-V35/V$8 -> 0.13162206 | ... Y36: =-Y35/Y$8 -> 0.10818213
B37: Segment information - MRO
B38: Commercial maintenance business | C38: 1141 | D38: 1163 | E38: 1521 | F38: =M38-E38 -> 1234 | G38: 1640 | I38: 1711 | J38: 2081 | K38: 2214 | L38: =X38-K38 -> 2649 | M38: 2755 | O38: 1580.6 | P38: 1914.4 | Q38: 2285.3 | R38: 2799.8 | S38: 2711 | T38: 2522 | U38: 2741 | V38: 3616 | W38: 4141 | X38: 4863 | Y38: 5783
B39: other revenue | C39: 0 | D39: 0 | E39: 0 | F39: =M39-E39 -> 45 | I39: 0 | J39: 0 | K39: 90 | L39: =X39-K39 -> 113 | M39: 45 | O39: 0 | P39: 0 | Q39: 0 | R39: 0 | S39: 0 | T39: 0 | U39: 0 | V39: 0 | W39: 83 | X39: 203 | Y39: 177
A40: X | B40: Commercial maintenance buisness (MRO) | C40: =SUM(C37:C39) -> 1141 | D40: =SUM(D37:D39) -> 1163 | E40: =SUM(E37:E39) -> 1521 | F40: =SUM(F37:F39) -> 1279 | G40: =SUM(G37:G39) -> 1640 | I40: =I38+I39 -> 1711 | J40: =J38+J39 -> 2081 | K40: =K38+K39 -> 2304 | L40: =L38+L39 -> 2762 | M40: =M38+M39 -> 2800 | O40: =O38+O39 -> 1580.6 | P40: =P38+P39 -> 1914.4 | Q40: =Q38+Q39 -> 2285.3 | R40: =R38+R39 -> 2799.8 | S40: =S38+S39 -> 2711 | T40: =T38+T39 -> 2522 | U40: =U38+U39 -> 2741 | V40: =V38+V39 -> 3616 | ... Y40: =Y38+Y39 -> 5960 | Z40: =(X40/O40)^(1/(2024-2015))-1 -> 0.13816388
...

Sheet R&D Capitalization
B2: in € million | C2: 2025 | D2: 2024 | F2: Change against previous year | G2: in € million | H2: in %
B3: Commercial engine business (OEM) | C3: 256 | D3: 249 | F3: 7 | G3: 7 | H3: 2.7
B4: Military engine business (OEM) | C4: 115 | D4: 88 | F4: 27 | G4: 27 | H4: 31
B5: Commercial maintenance business (MRO) | C5: 5 | D5: 5 | F5: 1 | G5: 1 | H5: 10.6
B6: Total research and development expenses | C6: =C3+C4+C5 -> 376 | D6: =D3+D4+D5 -> 342 | F6: 35 | G6: 35 | H6: 10.1
B7: Refund of research and development expenses | C7: -138 | D7: -112 | F7: −26 | G7: −26 | H7: −23.3
B8: Research and development expenses – own contribution | C8: =C6+C7 -> 238 | D8: 231 | F8: 9 | G8: 9 | H8: 3.7
B9: Expenditure meeting recognition criteria for intangible assets
B10: Commercial and military engine business (OEM) | C10: -93 | D10: -93 | F10: 0 | G10: 0 | H10: 0
B11: Amortization of previously capitalized development expenses | C11: 36 | D11: 90 | F11: −54 | G11: −54 | H11: −60.3
B12: Research and development expenses – effect on profit or loss | C12: =C8+C10+C11 -> 181 | D12: =D8+D10+D11 -> 228 | F12: −46 | G12: −46 | H12: −20.1
B13: thereof: in gross profit | C13: 71 | D13: 122 | F13: −51 | G13: −51 | H13: −41.7
B14: thereof: in functional costs – research and development | C14: 111 | D14: 106 | F14: 5 | G14: 5 | H14: 4.8
B16: Joaquin - Useful life of R&D (# years) | C16: 8
B18: Adjustments - Joaquin
B19: (+) expensed R&D | C19: =C12 -> 181
B20: (-) notional R&D amortization | C20: =-C19/C16 -> -22.625

Sheet x

Sheet Alt Presentation
C2: Q3'2021 | D2: Q4'2021 | F2: Q1'2022 | G2: Q2'2022 | H2: Q3'2022 | I2: Q4'2022 | J2: Q1'2023 | K2: Q2'2023 | L2: Q3'2023 | M2: Q4'2023 | N2: Q1'2024 | O2: Q2'2024 | P2: Q3'2024 | Q2: Q4'2024 | R2: Q1'2025 | S2: Q2'2025 | T2: TTM Figures
B3: Revenue | C3: 1349 | D3: 1180 | E3: 0 | F3: 1180 | G3: 1289 | H3: 1004 | I3: 1513 | J3: 1544 | K3: 1549 | L3: 560 | M3: 2125 | N3: 1650 | O3: 1740 | P3: 1897 | Q3: 1711 | R3: 2111 | S3: 2087
B4: Adjusted revenue | C4: 1349 | D4: 1180 | E4: 0 | F4: 1180 | G4: 1289 | H4: 1004 | I4: 1513 | J4: 1544 | K4: 1549 | L4: 1525 | M4: 2195 | N4: 1675 | O4: 1755 | P4: 1864 | Q4: 1678 | R4: 2092 | S4: 2048 | T4: =S4+R4+Q4+P4 -> 7682
B5: Y/Y growth | H5: =H4/C4-1 -> -0.255745 | I5: =I4/D4-1 -> 0.28220339 | J5: =J4/F4-1 -> 0.30847458 | K5: =K4/G4-1 -> 0.20170675 | L5: =L4/H4-1 -> 0.5189243 | M5: =M4/I4-1 -> 0.45076008 | N5: =N4/J4-1 -> 0.08484456 | O5: =O4/K4-1 -> 0.13298903 | P5: =P4/L4-1 -> 0.22229508 | Q5: =Q4/M4-1 -> -0.23553531 | ... S5: =S4/O4-1 -> 0.16695157
B6: Segment-level P&L
B7: Commercial engine business revenue | C7: 350 | D7: 300 | E7: 0 | F7: 278 | G7: 318 | H7: 251 | I7: 388 | J7: 446 | K7: 387 | L7: 393 | M7: 551 | N7: 433 | O7: 470 | P7: 465 | Q7: 419 | R7: 507 | S7: 645 | T7: =S7+R7+Q7+P7 -> 2036
B8: Military engine business | C8: 95 | D8: 172 | E8: 0 | F8: 108 | G8: 106 | H8: 123 | I8: 187 | J8: 103 | K8: 126 | L8: 138 | M8: 186 | N8: 124 | O8: 148 | P8: 153 | Q8: 171 | R8: 113 | S8: 147 | T8: =S8+R8+Q8+P8 -> 584
B9: OEM business | C9: =C7+C8 -> 445 | D9: =D7+D8 -> 472 | E9: =E7+E8 -> 0 | F9: =F7+F8 -> 386 | G9: =G7+G8 -> 424 | H9: =H7+H8 -> 374 | I9: =I7+I8 -> 575 | J9: =J7+J8 -> 549 | ... S9: =S7+S8 -> 792 | T9: =S9+R9+Q9+P9 -> 2620
B10: Commercial Maintenance | C10: 933 | D10: 731 | E10: 0 | F10: 819 | G10: 892 | H10: 658 | I10: 973 | J10: 1021 | K10: 1060 | L10: 1026 | M10: 1489 | N10: 1141 | O10: 1163 | P10: 1274 | Q10: 1117 | R10: 1521 | S10: 1278 | T10: =S10+R10+Q10+P10 -> 5190
B11: Mix
B12: OEM | C12: =C9/C$4 -> 0.32987398 | D12: =D9/D$4 -> 0.4 | E12: =E9/E$4 -> #DIV/0! | F12: =F9/F$4 -> 0.32711864 | G12: =G9/G$4 -> 0.32893716 | H12: =H9/H$4 -> 0.37250996 | I12: =I9/I$4 -> 0.38003966 | J12: =J9/J$4 -> 0.35556995 | ... T12: =T9/T$4 -> 0.34105702
B13: Maintenance | C13: =C10/C$4 -> 0.69162342 | D13: =D10/D$4 -> 0.61949153 | E13: =E10/E$4 -> #DIV/0! | F13: =F10/F$4 -> 0.6940678 | G13: =G10/G$4 -> 0.69200931 | H13: =H10/H$4 -> 0.65537849 | I13: =I10/I$4 -> 0.64309319 | J13: =J10/J$4 -> 0.66126943 | ... T13: =T10/T$4 -> 0.67560531
B14: EBIT (reported) | G14: 159 | K14: 193 | M14: 233 | N14: 188 | O14: 232 | Q14: 249 | R14: 314 | S14: 390 | T14: =S14+R14+Q14+P14 -> 953
B15: OEM business EBIT | C15: 86 | D15: 118 | E15: 0 | F15: 78 | G15: 87 | H15: 89 | I15: 136 | J15: 141 | K15: 121 | L15: 111 | M15: 168 | N15: 130 | O15: 157 | P15: 156 | Q15: 115 | R15: 176 | S15: 239 | T15: =S15+R15+Q15+P15 -> 686
B16: Commercial maintenance business EBIT | C16: 72 | D16: 44 | E16: 0 | F16: 53 | G16: 72 | H16: 28 | I16: 72 | J16: 70 | K16: 72 | L16: 81 | M16: 138 | N16: 88 | O16: 95 | P16: 118 | Q16: 106 | R16: 125 | S16: 116 | T16: =S16+R16+Q16+P16 -> 465
B17: Adjusted EBIT: | C17: =C15+C16 -> 158 | D17: =D15+D16 -> 162 | E17: =E15+E16 -> 0 | F17: =F15+F16 -> 131 | G17: =G15+G16 -> 159 | H17: =H15+H16 -> 117 | I17: =I15+I16 -> 208 | J17: =J15+J16 -> 211 | ... S17: =S15+S16 -> 355 | T17: =S17+R17+Q17+P17 -> 1151
B18: OEM business EBIT mgn | C18: =C15/C9 -> 0.19325843 | D18: =D15/D9 -> 0.25 | E18: =E15/E9 -> #DIV/0! | F18: =F15/F9 -> 0.20207254 | G18: =G15/G9 -> 0.20518868 | H18: =H15/H9 -> 0.23796791 | I18: =I15/I9 -> 0.23652174 | J18: =J15/J9 -> 0.2568306 | ... T18: =T15/T9 -> 0.26183206
B19: Commercial maintenance business EBIT mgn | C19: =C16/C10 -> 0.077170418 | D19: =D16/D10 -> 0.060191518 | E19: =E16/E10 -> #DIV/0! | F19: =F16/F10 -> 0.064713065 | G19: =G16/G10 -> 0.080717489 | H19: =H16/H10 -> 0.042553191 | I19: =I16/I10 -> 0.073997945 | J19: =J16/J10 -> 0.068560235 | ... T19: =T16/T10 -> 0.089595376
B20: EBIT mgn | C20: =C17/C4 -> 0.1171238 | D20: =D17/D4 -> 0.13728814 | E20: =E17/E4 -> #DIV/0! | F20: =F17/F4 -> 0.11101695 | G20: =G17/G4 -> 0.12335144 | H20: =H17/H4 -> 0.11653386 | I20: =I17/I4 -> 0.13747521 | J20: =J17/J4 -> 0.13665803 | ... T20: =T17/T4 -> 0.14983077
B21: Adjusted Net Income | C21: 113 | D21: 122 | E21: 0 | F21: 93 | G21: 114 | H21: 85 | I21: 156 | J21: 157 | K21: 143 | L21: 138 | M21: 223 | N21: 158 | O21: 185 | P21: 199 | Q21: 155 | R21: 221 | S21: 258
B22: Net Income mgn | C22: =C21/C4 -> 0.083765752 | D22: =D21/D4 -> 0.10338983 | E22: =E21/E4 -> #DIV/0! | F22: =F21/F4 -> 0.078813559 | G22: =G21/G4 -> 0.088440652 | H22: =H21/H4 -> 0.084661355 | I22: =I21/I4 -> 0.10310641 | J22: =J21/J4 -> 0.10168394 | ... S22: =S21/S4 -> 0.12597656
B23: Reported Net Income | C23: 92 | D23: 41 | E23: 0 | F23: 53 | G23: 66 | H23: 87 | I23: 121 | J23: 134 | K23: 122 | L23: -568 | M23: 143 | N23: 126 | O23: 162 | P23: 211 | Q23: 215 | R23: 224 | S23: 289
B24: EPS | C24: 1.74 | D24: 0.67 | E24: 0 | F24: 0.99 | G24: 1.24 | H24: 1.62 | I24: 2.23 | J24: 2.47 | K24: 2.28 | L24: -10.61 | M24: 2.56 | N24: 2.35 | O24: 2.96 | P24: 3.9 | Q24: 3.96 | R24: 4.03 | S24: 5.34
B25: Adjusted EPS | C25: 1.74 | D25: 0 | E25: 0 | F25: 0 | G25: 1.24 | H25: 1.62 | I25: 0 | J25: 0 | K25: 2.28 | L25: 2.56 | M25: 4.05 | N25: 2.93 | O25: 3.38 | P25: 3.68 | Q25: 2.8 | R25: 3.99 | S25: 4.77
B26: Non-IFRS:
B27: Reported EBITDA | C27: 220 | D27: 221 | E27: 0 | F27: 278 | G27: 216 | H27: 189 | I27: 255 | J27: 0 | K27: 259 | L27: -711 | M27: 405 | N27: 275 | O27: 321 | P27: 422 | Q27: 344 | R27: 417 | S27: 491 | T27: =S27+R27+Q27+P27 -> 1674
B28: Adjusted EBITDA | C28: 220 | D28: 221 | E28: 0 | F28: 278 | G28: 216 | H28: 189 | I28: 255 | J28: 0 | K28: 259 | L28: 264 | M28: 468 | N28: 294 | O28: 330 | P28: 383 | Q28: 305 | R28: 392 | S28: 446 | T28: =S28+R28+Q28+P28 -> 1526
B29: FCF | C29: 52 | D29: 35 | E29: 0 | F29: 93 | G29: 33 | H29: 18 | I29: 107 | J29: 0 | K29: 42 | L29: 122 | M29: -30 | N29: 16 | O29: 90 | P29: 108 | Q29: 95 | R29: 150 | S29: 61 | T29: =S29+R29+Q29+P29 -> 414
B30: Company-funded R&D | C30: 46 | D30: 44 | E30: 0 | F30: 47 | G30: 54 | H30: 41 | I30: 54 | J30: 0 | K30: 72 | L30: 51 | M30: 58 | N30: 56 | O30: 72 | P30: 45 | Q30: 53 | R30: 78 | S30: 50 | T30: =S30+R30+Q30+P30 -> 226
B31: Customer-funded R&D | C31: 10 | D31: 24 | E31: 0 | F31: 21 | G31: 17 | H31: 19 | I31: 20 | J31: 0 | K31: 18 | L31: 15 | M31: 30 | N31: 24 | O31: 27 | P31: 30 | Q31: 28 | R31: 30 | S31: 33 | T31: =S31+R31+Q31+P31 -> 121
B32: R&D expense | C32: =C31+C30 -> 56 | D32: =D31+D30 -> 68 | E32: =E31+E30 -> 0 | F32: =F31+F30 -> 68 | G32: =G31+G30 -> 71 | H32: =H31+H30 -> 60 | I32: =I31+I30 -> 74 | J32: =J31+J30 -> 0 | ... T32: =T31+T30 -> 347
B33: CapEx on PPE | C33: 78 | D33: 125 | E33: 0 | F33: 62 | G33: 54 | H33: 54 | I33: 136 | J33: 0 | K33: 50 | L33: 78 | M33: 153 | N33: 74 | O33: 97 | P33: 77 | Q33: 112 | R33: 76 | S33: 51
B34: Balance sheet:
B35: Intangibles | C35: 0 | D35: 1128 | E35: 0 | F35: 0 | G35: 0 | H35: 1136 | I35: 1151 | J35: 1151 | K35: 1154 | L35: 0 | M35: 1200 | N35: 0 | O35: 0 | P35: 1213 | Q35: 1313 | R35: 1310 | S35: 1429
B36: Cash & equivalents | C36: 0 | D36: 722 | E36: 0 | F36: 0 | G36: 0 | H36: 775 | I36: 823 | J36: 892 | K36: 771 | L36: 0 | M36: 883 | N36: 0 | O36: 0 | P36: 1910 | Q36: 1747 | R36: 1840 | S36: 1273
B37: Pension provision | C37: 0 | D37: 948 | E37: 0 | F37: 0 | G37: 0 | H37: 746 | I37: 707 | J37: 710 | K37: 721 | L37: 0 | M37: 743 | N37: 0 | O37: 0 | P37: 727 | Q37: 724 | R37: 727 | S37: 713
B38: Equity | C38: 0 | D38: 2760 | E38: 0 | F38: 0 | G38: 0 | H38: 2871 | I38: 3107 | J38: 3273 | K38: 3268 | L38: 0 | M38: 2933 | N38: 0 | O38: 0 | P38: 3350 | Q38: 3438 | R38: 3694 | S38: 3909
B39: Net financial debt | C39: 0 | D39: 673 | E39: 0 | F39: 0 | G39: 0 | H39: 604 | I39: 753 | J39: 646 | K39: 777 | L39: 0 | M39: 631 | N39: 0 | O39: 0 | P39: 631 | Q39: 1061 | R39: 972 | S39: 1147
B40: total assets & liabilities | C40: 0 | D40: 8304 | E40: 0 | F40: 0 | G40: 0 | H40: 9064 | I40: 9230 | J40: 9261 | K40: 9280 | L40: 0 | M40: 10204 | N40: 0 | O40: 0 | P40: 11810 | Q40: 12484 | R40: 12185 | S40: 11781
B41: Order backlog | C41: 0 | D41: 22237 | E41: 0 | F41: 0 | G41: 0 | H41: 25958 | I41: 22273 | J41: 22743 | K41: 21923 | L41: 0 | M41: 24393 | N41: 0 | O41: 0 | P41: 23359 | Q41: 28730 | R41: 27700 | S41: 25037
...
