Workbook

Sheet Main
B2: #VALUE!
B3: Price | C3: {=_FV(B2,"Price")} -> 326.1 | E3: CEO: | F3: Olivier Andries
B4: 52wh | C4: {=_FV(B2,"52 week high",TRUE)} -> 350.8 | F4: Worked in French Ministry of Industry + Treasury Dept
B5: 52wl | C5: {=_FV(B2,"52 week low",TRUE)} -> 190.7 | F5: Director, Strategy EADS
B6: Shares outstanding (M) | C6: {=_FV(B2,"Shares outstanding",TRUE)/1000000} -> 418.3446 | E6: CEO, Aircraft Engines | F6: Stéphane Cueille
B7: Market Cap | C7: {=_FV(B2,"Market cap",TRUE)/1000000} -> 136296.7 | F7: French Defense Procurement agency
B8: Cash | C8: =Sheet2!AJ105 -> 6707 | F8: Safran Nacelles - 2013
B9: Debt | C9: =Sheet2!AJ117+Sheet2!AJ123 -> 4838 | F9: PhD in Physics + ret. Colonel french armament engineering corps
B10: Convertibles | D10: <= These converted on May 30, 2024 | E10: CEO, Electronics & Defence | F10: Franck Saudo
B11: EV | C11: =C7-C8+C9+C10 -> 134427.7 | F11: head of financial markets, Ministre de l'economie
B12: TTM Revenue | C12: =Sheet2!AJ51+Sheet2!AI51 -> 29039
B13: TTM Earnings | C13: =Sheet2!AJ78+Sheet2!AI78 -> 4431
B14: TTM EPS | C14: =C13/C6 -> 10.591747
B15: PE | C15: {=_FV(B2,"P/E",TRUE)} -> 16.2271
B17: BV | C17: =Sheet2!AJ112 -> 13222
B18: BV/Share | C18: =C17/C6 -> 31.605523
B19: Multiple | C19: =C3/C18 -> 10.317817
B21: Accounting Lesson
B22: IAS38- capitalizing R&D
B25: VIC pitch:
B26: https://www.valueinvestorsclub.com/idea/SAFRAN_SA/5053975887

Sheet Dashboard
C2: =Main!B2 -> #VALUE!
B3: Operating margin | C3: =Sheet2!AU70 -> 0.15124838
B4: Return on Assets | C4: =(Sheet2!AU69*(1-0.3))/AVERAGE(Sheet2!AU108,Sheet2!AT108) -> 0.055638984
B5: Return on Equity | C5: =Sheet2!AU79/AVERAGE(Sheet2!AU114,Sheet2!AT114) -> -0.058475431
B6: Revenue | C6: =Sheet2!AU52 -> 27716
B7: 5-year Revenue CAGR
B8: Gross Profit
B9: Total Debt/Equity | C9: =(Sheet2!AJ123+Sheet2!AJ117)/Sheet2!AJ114 -> 0.3511395
B10: Book Value Per Share
B11: 52 Week Change
B12: Market Cap
B13: Trailing P/E
B14: Price/Sales
B15: Price/Book

Sheet Sheet2
D2: Q1'2022 | E2: Q2'2022 | F2: Q3'2022 | G2: Q4'2022 | H2: Q1'2023 | I2: Q2'2023 | J2: Q3'2023 | K2: Q4'2023 | L2: Q1'2024 | M2: Q2'2024 | N2: Q3'2024 | O2: Q4'2024 | P2: Q1'2025 | Q2: Q2'2025 | R2: Q3'2025 | T2: 1H'2017 | U2: 2H'2017 | V2: 1H'2018 | W2: 2H'2018 | X2: 1H'2019 | Y2: 2H'2019 | Z2: 1H'2020 | AA2: 2H'2020 | AB2: 1H'2021 | AC2: 2H'2021 | AD2: 1H'2022 | AE2: 2H'2022 | AF2: 1H'2023 | AG2: 2H'2023 | AH2: 1H'2024 | AI2: 2H'2024 | AJ2: 1H'2025 | AL2: FY2015 | AM2: FY2016 | AN2: FY2017 | AO2: FY2018 | AP2: FY2019 | AQ2: FY2020 | AR2: FY2021 | AS2: FY2022 | AT2: FY2023 | AU2: FY2024 | AV2: CAGR
C3: No. Units delivered
C4: LEAP engines | D4: 239 | E4: =AB4-D4 -> 160 | F4: 347 | G4: =AE4-F4 -> 324 | H4: 366 | I4: =AF4-H4 -> 419 | J4: 389 | K4: =AG4-J4 -> 396 | L4: 387 | M4: =AH4-L4 -> 277 | N4: 365 | O4: =AU4-N4-M4-L4 -> 378 | P4: 319 | Q4: =AJ4-P4 -> 345 | R4: 511 | T4: 147 | U4: =AN4-T4 -> 312 | V4: 438 | W4: =AO4-V4 -> 680 | X4: 861 | Y4: =AP4-X4 -> 875 | Z4: 450 | AA4: =AQ4-Z4 -> 365 | AB4: 399 | AC4: =AR4-AB4 -> 446 | AD4: 465 | AE4: =AS4-AD4 -> 671 | AF4: 785 | AG4: =AT4-AF4 -> 785 | AH4: 664 | AI4: =AU4-AH4 -> 743 | AJ4: 664 | AL4: 0 | AM4: 77 | AN4: 459 | AO4: 1118 | AP4: 1736 | AQ4: 815 | AR4: 845 | AS4: 1136 | AT4: 1570 | AU4: 1407
C5: CFM56 engines | D5: 15 | E5: =AB5-D5 -> 34 | F5: 17 | G5: =AE5-F5 -> 16 | H5: 15 | I5: =AF5-H5 -> 9 | J5: 14 | K5: =AG5-J5 -> 14 | L5: 12 | M5: =AH5-L5 -> 16 | N5: 13 | O5: =AU5-N5-M5-L5 -> 19 | P5: 12 | Q5: =AJ5-P5 -> 16 | R5: 15 | T5: 710 | U5: =AN5-T5 -> 734 | V5: 591 | W5: =AO5-V5 -> 453 | X5: 258 | Y5: =AP5-X5 -> 133 | Z5: 84 | AA5: =AQ5-Z5 -> 73 | AB5: 49 | AC5: =AR5-AB5 -> 58 | AD5: 27 | AE5: =AS5-AD5 -> 33 | AF5: 24 | AG5: =AT5-AF5 -> 28 | AH5: 28 | AI5: =AU5-AH5 -> 32 | AJ5: 28 | AL5: 1612 | AM5: 1693 | AN5: 1444 | AO5: 1044 | AP5: 391 | AQ5: 157 | AR5: 107 | AS5: 60 | AT5: 52 | AU5: 60
C6: High thrust engines | D6: 48 | E6: =AB6-D6 -> 90 | F6: 40 | G6: =AE6-F6 -> 50 | H6: 37 | I6: =AF6-H6 -> 46 | J6: 58 | K6: =AG6-J6 -> 49 | L6: 56 | M6: =AH6-L6 -> 35 | N6: 51 | O6: =AU6-N6-M6-L6 -> 53 | P6: 48 | Q6: =AJ6-P6 -> 43 | R6: 55 | T6: 256 | U6: =AN6-T6 -> 230 | V6: 201 | W6: =AO6-V6 -> 234 | X6: 234 | Y6: =AP6-X6 -> 255 | Z6: 197 | AA6: =AQ6-Z6 -> 172 | AB6: 138 | AC6: =AR6-AB6 -> 97 | AD6: 91 | AE6: =AS6-AD6 -> 90 | AF6: 83 | AG6: =AT6-AF6 -> 107 | AH6: 91 | AI6: =AU6-AH6 -> 104 | AJ6: 91 | AL6: 695 | AM6: 686 | AN6: 486 | AO6: 435 | AP6: 489 | AQ6: 369 | AR6: 235 | AS6: 181 | AT6: 190 | AU6: 195
C7: Helicopter turbines | D7: 110 | E7: =AB7-D7 -> 174 | F7: 128 | G7: =AE7-F7 -> 153 | H7: 136 | I7: =AF7-H7 -> 138 | J7: 140 | K7: =AG7-J7 -> 174 | L7: 136 | M7: =AH7-L7 -> 169 | N7: 181 | O7: =AU7-N7-M7-L7 -> 196 | P7: 153 | Q7: =AJ7-P7 -> 152 | R7: 192 | T7: 314 | U7: =AN7-T7 -> 358 | V7: 335 | W7: =AO7-V7 -> 438 | X7: 335 | Y7: =AP7-X7 -> 361 | Z7: 275 | AA7: =AQ7-Z7 -> 354 | AB7: 284 | AC7: =AR7-AB7 -> 290 | AD7: 227 | AE7: =AS7-AD7 -> 281 | AF7: 274 | AG7: =AT7-AF7 -> 314 | AH7: 305 | AI7: =AU7-AH7 -> 377 | AJ7: 305 | AL7: 625 | AM7: 714 | AN7: 672 | AO7: 773 | AP7: 696 | AQ7: 629 | AR7: 574 | AS7: 508 | AT7: 588 | AU7: 682
C8: M88 engines | D8: 12 | E8: =AB8-D8 -> 19 | F8: 9 | G8: =AE8-F8 -> 22 | H8: 17 | I8: =AF8-H8 -> 14 | J8: 8 | K8: =AG8-J8 -> 3 | L8: 8 | M8: =AH8-L8 -> 6 | N8: 10 | O8: =AU8-N8-M8-L8 -> 16 | P8: 2 | Q8: =AJ8-P8 -> 12 | R8: 7 | T8: 12 | U8: =AN8-T8 -> 21 | V8: 4 | W8: =AO8-V8 -> 19 | X8: 22 | Y8: =AP8-X8 -> 40 | Z8: 19 | AA8: =AQ8-Z8 -> 14 | AB8: 31 | AC8: =AR8-AB8 -> 33 | AD8: 20 | AE8: =AS8-AD8 -> 31 | AF8: 31 | AG8: =AT8-AF8 -> 11 | AH8: 14 | AI8: =AU8-AH8 -> 26 | AJ8: 14 | AL8: 12 | AM8: 11 | AN8: 33 | AO8: 23 | AP8: 62 | AQ8: 33 | AR8: 64 | AS8: 51 | AT8: 42 | AU8: 40
C9: A320 neo nacelles | D9: 141 | E9: =AB9-D9 -> 123 | F9: 153 | G9: =AE9-F9 -> 151 | H9: 135 | I9: =AF9-H9 -> 140 | J9: 153 | K9: =AG9-J9 -> 151 | L9: 135 | M9: =AH9-L9 -> 162 | N9: 142 | O9: =AU9-N9-M9-L9 -> 183 | P9: 155 | Q9: =AJ9-P9 -> 142 | R9: 166 | T9: 263 | U9: =AN9-T9 -> -28 | V9: 176 | W9: =AO9-V9 -> 262 | X9: 280 | Y9: =AP9-X9 -> 322 | Z9: 248 | AA9: =AQ9-Z9 -> 226 | AB9: 264 | AC9: =AR9-AB9 -> 312 | AD9: 284 | AE9: =AS9-AD9 -> 304 | AF9: 275 | AG9: =AT9-AF9 -> 304 | AH9: 297 | AI9: =AU9-AH9 -> 325 | AJ9: 297 | AL9: 0 | AM9: 0 | AN9: 235 | AO9: 438 | AP9: 602 | AQ9: 474 | AR9: 576 | AS9: 588 | AT9: 579 | AU9: 622
C10: A320 landing gear sets | D10: 346 | E10: =AB10-D10 -> -346 | F10: 8 | G10: =AE10-F10 -> -8 | H10: 126 | I10: =AF10-H10 -> 145 | J10: 126 | K10: =AG10-J10 -> 184 | L10: 167 | M10: =AH10-L10 -> 137 | N10: 159 | O10: =AU10-N10-M10-L10 -> 138 | P10: 171 | Q10: =AJ10-P10 -> 133 | R10: 186 | U10: =AN10-T10 -> 0 | W10: =AO10-V10 -> 0 | X10: 0 | Y10: =AP10-X10 -> 0 | Z10: 0 | AA10: =AQ10-Z10 -> 0 | AB10: 0 | AC10: =AR10-AB10 -> 0 | AD10: 0 | AE10: =AS10-AD10 -> 0 | AF10: 271 | AG10: =AT10-AF10 -> 310 | AH10: 304 | AI10: =AU10-AH10 -> 297 | AJ10: 304 | AL10: 0 | AM10: 0 | AN10: 0 | AO10: 0 | AP10: 0 | AQ10: 0 | AR10: 0 | AS10: 0 | AT10: 581 | AU10: 601
C11: A320 emegency slides | D11: 1106 | E11: =AB11-D11 -> 602 | F11: 1335 | G11: =AE11-F11 -> 1039 | H11: 779 | I11: =AF11-H11 -> 678 | J11: 1165 | K11: =AG11-J11 -> 1328 | L11: 1080 | M11: =AH11-L11 -> 882 | N11: 1256 | O11: =AU11-N11-M11-L11 -> 1223 | P11: 1186 | Q11: =AJ11-P11 -> 776 | R11: 1186 | U11: =AN11-T11 -> 0 | V11: 1296 | W11: =AO11-V11 -> 2330 | X11: 2398 | Y11: =AP11-X11 -> 2523 | Z11: 1524 | AA11: =AQ11-Z11 -> 1425 | AB11: 1708 | AC11: =AR11-AB11 -> 1890 | AD11: 2080 | AE11: =AS11-AD11 -> 2374 | AF11: 1457 | AG11: =AT11-AF11 -> 2493 | AH11: 1962 | AI11: =AU11-AH11 -> 2479 | AJ11: 1962 | AL11: 0 | AM11: 0 | AN11: 0 | AO11: 3626 | AP11: 4921 | AQ11: 2949 | AR11: 3598 | AS11: 4454 | AT11: 3950 | AU11: 4441
C12: A330 neo nacelles | D12: 12 | E12: =AB12-D12 -> -6 | F12: 10 | G12: =AE12-F12 -> 550 | H12: 8 | I12: =AF12-H12 -> 18 | J12: 12 | K12: =AG12-J12 -> 16 | L12: 16 | M12: =AH12-L12 -> 13 | N12: 13 | O12: =AU12-N12-M12-L12 -> 20 | P12: 20 | Q12: =AJ12-P12 -> 9 | R12: 14 | U12: =AN12-T12 -> 0 | W12: =AO12-V12 -> 0 | X12: 51 | Y12: =AP12-X12 -> 41 | Z12: 20 | AA12: =AQ12-Z12 -> 16 | AB12: 6 | AC12: =AR12-AB12 -> 14 | AD12: 28 | AE12: =AS12-AD12 -> 560 | AF12: 26 | AG12: =AT12-AF12 -> 28 | AH12: 29 | AI12: =AU12-AH12 -> 33 | AJ12: 29 | AL12: 0 | AM12: 65 | AN12: 0 | AO12: 0 | AP12: 92 | AQ12: 36 | AR12: 20 | AS12: 588 | AT12: 54 | AU12: 62
C13: A350 landing gear sets | D13: 10 | E13: =AB13-D13 -> 10 | F13: 8 | G13: =AE13-F13 -> 12 | H13: 12 | I13: =AF13-H13 -> 11 | J13: 11 | K13: =AG13-J13 -> 12 | L13: 15 | M13: =AH13-L13 -> 11 | N13: 11 | O13: =AU13-N13-M13-L13 -> 11 | P13: 13 | Q13: =AJ13-P13 -> 13 | R13: 9 | T13: 43 | U13: =AN13-T13 -> 38 | V13: 40 | W13: =AO13-V13 -> 40 | X13: 41 | Y13: =AP13-X13 -> 41 | Z13: 26 | AA13: =AQ13-Z13 -> 26 | AB13: 20 | AC13: =AR13-AB13 -> 19 | AD13: 23 | AE13: =AS13-AD13 -> 20 | AF13: 23 | AG13: =AT13-AF13 -> 23 | AH13: 26 | AI13: =AU13-AH13 -> 22 | AJ13: 26 | AL13: 0 | AM13: 0 | AN13: 81 | AO13: 80 | AP13: 82 | AQ13: 52 | AR13: 39 | AS13: 43 | AT13: 46 | AU13: 48
C14: A350 lavatories | D14: 71 | E14: =AB14-D14 -> 65 | F14: 53 | G14: =AE14-F14 -> 97 | H14: 106 | I14: =AF14-H14 -> 114 | J14: 99 | K14: =AG14-J14 -> 95 | L14: 81 | M14: =AH14-L14 -> 112 | N14: 139 | O14: =AU14-N14-M14-L14 -> 116 | P14: 51 | Q14: =AJ14-P14 -> 142 | R14: 126 | U14: =AN14-T14 -> 0 | V14: 241 | W14: =AO14-V14 -> 310 | X14: 400 | Y14: =AP14-X14 -> 371 | Z14: 199 | AA14: =AQ14-Z14 -> 153 | AB14: 136 | AC14: =AR14-AB14 -> 128 | AD14: 188 | AE14: =AS14-AD14 -> 150 | AF14: 220 | AG14: =AT14-AF14 -> 194 | AH14: 193 | AI14: =AU14-AH14 -> 255 | AJ14: 193 | AL14: 32 | AM14: 56 | AN14: 0 | AO14: 551 | AP14: 771 | AQ14: 352 | AR14: 264 | AS14: 338 | AT14: 414 | AU14: 448
C15: 787 landing gear sets | D15: 0 | E15: =AB15-D15 -> 25 | F15: 6 | G15: =AE15-F15 -> 14 | H15: 6 | I15: =AF15-H15 -> 4 | J15: 6 | K15: =AG15-J15 -> 14 | L15: 11 | M15: =AH15-L15 -> 9 | N15: 14 | O15: =AU15-N15-M15-L15 -> 7 | P15: 16 | Q15: =AJ15-P15 -> 4 | R15: 18 | T15: 66 | U15: =AN15-T15 -> 68 | V15: 74 | W15: =AO15-V15 -> 70 | X15: 84 | Y15: =AP15-X15 -> 81 | Z15: 62 | AA15: =AQ15-Z15 -> 58 | AB15: 25 | AC15: =AR15-AB15 -> 16 | AD15: 1 | AE15: =AS15-AD15 -> 20 | AF15: 10 | AG15: =AT15-AF15 -> 20 | AH15: 20 | AI15: =AU15-AH15 -> 21 | AJ15: 20 | AL15: 0 | AM15: 0 | AN15: 134 | AO15: 144 | AP15: 165 | AQ15: 120 | AR15: 41 | AS15: 21 | AT15: 30 | AU15: 41
C16: 787 primary power distribution systems | D16: 8 | E16: =AB16-D16 -> 126 | F16: 31 | G16: =AE16-F16 -> 52 | H16: 61 | I16: =AF16-H16 -> 66 | J16: 65 | K16: =AG16-J16 -> 90 | L16: 88 | M16: =AH16-L16 -> 81 | N16: 86 | O16: =AU16-N16-M16-L16 -> 89 | P16: 88 | Q16: =AJ16-P16 -> 81 | R16: 97 | U16: =AN16-T16 -> 0 | V16: 296 | W16: =AO16-V16 -> 424 | X16: 561 | Y16: =AP16-X16 -> 493 | Z16: 417 | AA16: =AQ16-Z16 -> 340 | AB16: 134 | AC16: =AR16-AB16 -> 25 | AD16: 29 | AE16: =AS16-AD16 -> 83 | AF16: 127 | AG16: =AT16-AF16 -> 155 | AH16: 169 | AI16: =AU16-AH16 -> 175 | AJ16: 169 | AL16: 127 | AM16: 128 | AN16: 0 | AO16: 720 | AP16: 1054 | AQ16: 757 | AR16: 159 | AS16: 112 | AT16: 282 | AU16: 344
C17: biz & regional jets small nacelles | D17: 117 | E17: =AB17-D17 -> 70 | F17: 113 | G17: =AE17-F17 -> 133 | H17: 134 | I17: =AF17-H17 -> 136 | J17: 137 | K17: =AG17-J17 -> 105 | L17: 121 | M17: =AH17-L17 -> 275 | N17: 169 | O17: =AU17-N17-M17-L17 -> 189 | P17: 181 | Q17: =AJ17-P17 -> 215 | R17: 195 | T17: 234 | U17: =AN17-T17 -> 243 | V17: 309 | W17: =AO17-V17 -> 339 | X17: 304 | Y17: =AP17-X17 -> 331 | Z17: 246 | AA17: =AQ17-Z17 -> 189 | AB17: 187 | AC17: =AR17-AB17 -> 205 | AD17: 270 | AE17: =AS17-AD17 -> 246 | AF17: 270 | AG17: =AT17-AF17 -> 242 | AH17: 396 | AI17: =AU17-AH17 -> 358 | AJ17: 396 | AL17: 711 | AM17: 600 | AN17: 477 | AO17: 648 | AP17: 635 | AQ17: 435 | AR17: 392 | AS17: 516 | AT17: 512 | AU17: 754
C18: Business class seats | D18: 346 | E18: =AB18-D18 -> 341 | F18: 377 | G18: =AE18-F18 -> 509 | H18: 324 | I18: =AF18-H18 -> 112 | J18: 174 | K18: =AG18-J18 -> 373 | L18: 242 | M18: =AH18-L18 -> 508 | N18: 592 | O18: =AU18-N18-M18-L18 -> 1140 | P18: 704 | Q18: =AJ18-P18 -> 46 | R18: 428 | U18: =AN18-T18 -> 0 | V18: 1495 | W18: =AO18-V18 -> 1919 | X18: 2537 | Y18: =AP18-X18 -> 3097 | Z18: 1689 | AA18: =AQ18-Z18 -> 1046 | AB18: 687 | AC18: =AR18-AB18 -> 1410 | AD18: 818 | AE18: =AS18-AD18 -> 886 | AF18: 436 | AG18: =AT18-AF18 -> 547 | AH18: 750 | AI18: =AU18-AH18 -> 1732 | AJ18: 750 | AL18: 0 | AM18: 0 | AN18: 0 | AO18: 3414 | AP18: 5634 | AQ18: 2735 | AR18: 2097 | AS18: 1704 | AT18: 983 | AU18: 2482
C19: A380 nacelles | T19: 21 | U19: =AN19-T19 -> 85 | V19: 20 | W19: =AO19-V19 -> 56 | X19: 12 | Y19: =AP19-X19 -> 12 | Z19: 8 | AA19: =AQ19-Z19 -> 9 | AL19: 104 | AM19: 99 | AN19: 106 | AO19: 76 | AP19: 24 | AQ19: 17
C20: A320 thrust reversers | U20: =AN20-T20 -> 504 | W20: =AO20-V20 -> 310 | X20: 105 | Y20: =AP20-X20 -> 38 | Z20: 29 | AA20: =AQ20-Z20 -> 15 | AL20: 564 | AM20: 548 | AN20: 504 | AO20: 310 | AP20: 143 | AQ20: 44
C21: A330 thrust reversers | T21: 52 | V21: 50 | AL21: 130 | AM21: 91
C22: Spaceflex V2 (A320 lavs and galleys) | U22: =AN22-T22 -> 0 | V22: 178 | W22: =AO22-V22 -> 248 | X22: 197 | Y22: =AP22-X22 -> 172 | Z22: 167 | AA22: =AQ22-Z22 -> 144 | AL22: 0 | AM22: 0 | AN22: 0 | AO22: 426 | AP22: 369 | AQ22: 311
B24: X | C24: Revenue-level information
C25: Propulsion
C26: Revenue | D26: 1942 | E26: 2234 | F26: 2503 | G26: 2827 | H26: 2714 | I26: 2963 | J26: 3083 | K26: 3116 | L26: 3097 | M26: 3364 | N26: 3339 | O26: 3852 | P26: 3684 | Q26: 3857 | R26: 4044 | T26: 4414 | U26: =AN26-T26 -> 4943 | V26: 4744 | W26: =AO26-V26 -> 5708 | X26: 5902 | Y26: =AP26-X26 -> 6143 | Z26: 4047 | AA26: =AQ26-Z26 -> 3616 | AB26: 3249 | AC26: =AR26-AB26 -> 4190 | AD26: 4176 | AE26: =AS26-AD26 -> 5330 | AF26: =H26+I26 -> 5677 | AG26: =AT26-AF26 -> 6199 | AH26: =L26+M26 -> 6461 | AI26: =AU26-AH26 -> 7191 | AJ26: 7541 | AL26: 9319 | AM26: 9391 | AN26: 9357 | AO26: 10452 | AP26: 12045 | AQ26: 7663 | AR26: 7439 | AS26: 9506 | AT26: 11876 | AU26: 13652
C27: Operating Income | T27: 721 | U27: =AN27-T27 -> 795 | V27: 868 | W27: =AO27-V27 -> 1061 | X27: 1227 | Y27: =AP27-X27 -> 1258 | Z27: 699 | AA27: =AQ27-Z27 -> 493 | AB27: 504 | AC27: =AR27-AB27 -> 838 | AD27: 723 | AE27: =AS27-AD27 -> 987 | AF27: 1051 | AG27: =AT27-AF27 -> 1339 | AH27: 1285 | AI27: =AU27-AH27 -> 1534 | AJ27: 1758 | AL27: 1833 | AM27: 1786 | AN27: 1516 | AO27: 1929 | AP27: 2485 | AQ27: 1192 | AR27: 1342 | AS27: 1710 | AT27: 2390 | AU27: 2819
C28: One-off item | T28: 0 | U28: =AN28-T28 -> -40 | V28: -1 | W28: =AO28-V28 -> -30 | X28: 0 | Y28: =AP28-X28 -> -7 | Z28: -20 | AA28: =AQ28-Z28 -> -137 | AB28: -133 | AC28: =AR28-AB28 -> -177 | AD28: -129 | AE28: =AS28-AD28 -> -15 | AF28: -5 | AG28: =AT28-AF28 -> -47 | AH28: 1 | AI28: =AU28-AH28 -> -27 | AJ28: 1 | AL28: -619 | AM28: 3 | AN28: -40 | AO28: -31 | AP28: -7 | AQ28: -157 | AR28: -310 | AS28: -144 | AT28: -52 | AU28: -26
C29: Profit (loss) from operations. | T29: =T27+T28 -> 721 | U29: =U27+U28 -> 755 | V29: =V27+V28 -> 867 | W29: =W27+W28 -> 1031 | X29: =X27+X28 -> 1227 | Y29: =Y27+Y28 -> 1251 | Z29: =Z27+Z28 -> 679 | AA29: =AA27+AA28 -> 356 | ... AJ29: =AJ27+AJ28 -> 1759 | AL29: =AL27+AL28 -> 1214 | AM29: =AM27+AM28 -> 1789 | AN29: =AN27+AN28 -> 1476 | AO29: =AO27+AO28 -> 1898 | AP29: =AP27+AP28 -> 2478 | AQ29: =AQ27+AQ28 -> 1035 | AR29: =AR27+AR28 -> 1032 | AS29: =AS27+AS28 -> 1566 | ... AU29: =AU27+AU28 -> 2793 | AV29: =((AU29/AL29)^(1/(2024-2015)))-1 -> 0.096997923
C30: mgn | T30: =T29/T26 -> 0.16334391 | U30: =U29/U26 -> 0.15274125 | V30: =V29/V26 -> 0.18275717 | W30: =W29/W26 -> 0.18062369 | X30: =X29/X26 -> 0.20789563 | Y30: =Y29/Y26 -> 0.20364643 | Z30: =Z29/Z26 -> 0.1677786 | AA30: =AA29/AA26 -> 0.098451327 | ... AJ30: =AJ29/AJ26 -> 0.23325819 | AK30: =(AI29+AJ29)/(AJ26+AI26) -> 0.22169427 | AL30: =AL29/AL26 -> 0.13027149 | AM30: =AM29/AM26 -> 0.19050154 | AN30: =AN29/AN26 -> 0.15774287 | AO30: =AO29/AO26 -> 0.18159204 | AP30: =AP29/AP26 -> 0.20572852 | AQ30: =AQ29/AQ26 -> 0.1350646 | AR30: =AR29/AR26 -> 0.13872832 | AS30: =AS29/AS26 -> 0.16473806 | ... AU30: =AU29/AU26 -> 0.20458541 | AV30: =((AU30/AL30)^(1/(2024-2015)))-1 -> 0.051430538
C31: Equipment & defense
C32: Revenue | D32: 1716 | E32: 1790 | F32: 1820 | G32: 2209 | H32: 1966 | I32: 2134 | J32: 2134 | K32: 3601 | L32: 2444 | M32: 2726 | N32: 2527 | O32: 1921 | P32: 2783 | Q32: 2826 | R32: 3004 | T32: =2636+612 -> 3248 | U32: =AN32-T32 -> 2012 | V32: =2585+651 -> 3236 | W32: =AO32-V32 -> 2159 | X32: 4553 | Y32: =AP32-X32 -> 4703 | Z32: 3638 | AA32: =AQ32-Z32 -> 3255 | AB32: 2972 | AC32: =AR32-AB32 -> 3353 | AD32: 3506 | AE32: =AS32-AD32 -> 4029 | AF32: =H32+I32 -> 4100 | AG32: =AT32-AF32 -> 4735 | AH32: =L32+M32 -> 5170 | AI32: =AU32-AH32 -> 5448 | AJ32: 5609 | AL32: =4943+1266 -> 6209 | AM32: =5145+1238 -> 6383 | AN32: 5260 | AO32: 5395 | AP32: 9256 | AQ32: 6893 | AR32: 6325 | AS32: 7535 | AT32: 8835 | AU32: 10618
C33: Operating Income | T33: =287+35 -> 322 | U33: =AN33-T33 -> 297 | V33: =347+45 -> 392 | W33: =AO33-V33 -> 378 | X33: 588 | Y33: =AP33-X33 -> 621 | Z33: 343 | AA33: =AQ33-Z33 -> 344 | AB33: 270 | AC33: =AR33-AB33 -> 380 | AD33: 411 | AE33: =AS33-AD33 -> 463 | AF33: 466 | AG33: =AT33-AF33 -> 526 | AH33: 657 | AI33: =AU33-AH33 -> 641 | AJ33: 703 | AL33: =466+64 -> 530 | AM33: =567+76 -> 643 | AN33: 619 | AO33: 770 | AP33: 1209 | AQ33: 687 | AR33: 650 | AS33: 874 | AT33: 992 | AU33: 1298
C34: One-off item | T34: 0 | U34: =AN34-T34 -> -14 | V34: =6+0 -> 6 | W34: =AO34-V34 -> -17 | X34: -1 | Y34: =AP34-X34 -> -20 | Z34: -73 | AA34: =AQ34-Z34 -> -160 | AB34: -59 | AC34: =AR34-AB34 -> -27 | AD34: 42 | AE34: =AS34-AD34 -> -2 | AF34: -7 | AG34: =AT34-AF34 -> -6 | AH34: -12 | AI34: =AU34-AH34 -> 77 | AJ34: -8 | AL34: =-43-10 -> -53 | AM34: =-5-7 -> -12 | AN34: -14 | AO34: -11 | AP34: -21 | AQ34: -233 | AR34: -86 | AS34: 40 | AT34: -13 | AU34: 65
C35: Profit (loss) from operations. | T35: =T33+T34 -> 322 | U35: =U33+U34 -> 283 | V35: =V33+V34 -> 398 | W35: =W33+W34 -> 361 | X35: =X33+X34 -> 587 | Y35: =Y33+Y34 -> 601 | Z35: =Z33+Z34 -> 270 | AA35: =AA33+AA34 -> 184 | ... AJ35: =AJ33+AJ34 -> 695 | AL35: =AL33+AL34 -> 477 | AM35: =AM33+AM34 -> 631 | AN35: =AN33+AN34 -> 605 | AO35: =AO33+AO34 -> 759 | AP35: =AP33+AP34 -> 1188 | AQ35: =AQ33+AQ34 -> 454 | AR35: =AR33+AR34 -> 564 | AS35: =AS33+AS34 -> 914 | ... AU35: =AU33+AU34 -> 1363 | AV35: =((AU35/AL35)^(1/(2024-2015)))-1 -> 0.12373566
C36: mgn | T36: =T35/T32 -> 0.099137931 | U36: =U35/U32 -> 0.14065606 | V36: =V35/V32 -> 0.12299135 | W36: =W35/W32 -> 0.16720704 | X36: =X35/X32 -> 0.12892598 | Y36: =Y35/Y32 -> 0.12779077 | Z36: =Z35/Z32 -> 0.074216603 | AA36: =AA35/AA32 -> 0.056528418 | ... AJ36: =AJ35/AJ32 -> 0.123908 | AL36: =AL35/AL32 -> 0.076823965 | AM36: =AM35/AM32 -> 0.098856337 | AN36: =AN35/AN32 -> 0.11501901 | AO36: =AO35/AO32 -> 0.14068582 | AP36: =AP35/AP32 -> 0.12834918 | AQ36: =AQ35/AQ32 -> 0.06586392 | AR36: =AR35/AR32 -> 0.08916996 | AS36: =AS35/AS32 -> 0.1213006 | ... AU36: =AU35/AU32 -> 0.12836692 | AV36: =((AU36/AL36)^(1/(2024-2015)))-1 -> 0.058700054
C37: Aircraft interiors
C38: Revenue | D38: 409 | E38: 461 | F38: 522 | G38: 586 | H38: 584 | I38: 579 | J38: 605 | K38: 709 | L38: 676 | M38: 735 | N38: 771 | O38: 855 | P38: 788 | Q38: 828 | R38: 802 | T38: 0 | U38: =AN38-T38 -> 1316 | V38: =742+774 -> 1516 | W38: =AO38-V38 -> -130 | X38: 1640 | Y38: =AP38-X38 -> 1681 | Z38: 1072 | AA38: =AQ38-Z38 -> 850 | AB38: 646 | AC38: =AR38-AB38 -> 829 | AD38: 870 | AE38: =AS38-AD38 -> 1108 | AF38: =H38+I38 -> 1163 | AG38: =AT38-AF38 -> 1314 | AH38: =L38+M38 -> 1411 | AI38: =AU38-AH38 -> 1626 | AJ38: 1616 | AN38: 1316 | AO38: 1386 | AP38: 3321 | AQ38: 1922 | AR38: 1475 | AS38: 1978 | AT38: 2477 | AU38: 3037
C39: Operating Income | T39: 0 | U39: =AN39-T39 -> 93 | V39: =129+0 -> 129 | W39: =AO39-V39 -> -11 | X39: 85 | Y39: =AP39-X39 -> 103 | Z39: -101 | AA39: =AQ39-Z39 -> -73 | AB39: -110 | AC39: =AR39-AB39 -> -57 | AD39: -82 | AE39: =AS39-AD39 -> -58 | AF39: -100 | AG39: =AT39-AF39 -> -16 | AH39: 10 | AI39: =AU39-AH39 -> 17 | AJ39: 27 | AN39: 93 | AO39: 118 | AP39: 188 | AQ39: -174 | AR39: -167 | AS39: -140 | AT39: -116 | AU39: 27
C40: One-off item | T40: 0 | U40: =AN40-T40 -> -14 | V40: =-1-2 -> -3 | W40: =AO40-V40 -> 6 | X40: -1 | Y40: =AP40-X40 -> -5 | Z40: -51 | AA40: =AQ40-Z40 -> -21 | AB40: -1 | AC40: =AR40-AB40 -> -16 | AD40: -4 | AE40: =AS40-AD40 -> -342 | AF40: -38 | AG40: =AT40-AF40 -> -390 | AH40: -9 | AI40: =AU40-AH40 -> -36 | AJ40: -29 | AN40: -14 | AO40: 3 | AP40: -6 | AQ40: -72 | AR40: -17 | AS40: -346 | AT40: -428 | AU40: -45
C41: Profit (loss) from operations. | T41: =T39+T40 -> 0 | U41: =U39+U40 -> 79 | V41: =V39+V40 -> 126 | W41: =W39+W40 -> -5 | X41: =X39+X40 -> 84 | Y41: =Y39+Y40 -> 98 | Z41: =Z39+Z40 -> -152 | AA41: =AA39+AA40 -> -94 | ... AJ41: =AJ39+AJ40 -> -2 | AN41: =AN39+AN40 -> 79 | AO41: =AO39+AO40 -> 121 | AP41: =AP39+AP40 -> 182 | AQ41: =AQ39+AQ40 -> -246 | AR41: =AR39+AR40 -> -184 | AS41: =AS39+AS40 -> -486 | AT41: =AT39+AT40 -> -544 | AU41: =AU39+AU40 -> -18
C42: mgn | T42: =T41/T38 -> #DIV/0! | U42: =U41/U38 -> 0.060030395 | V42: =V41/V38 -> 0.083113456 | W42: =W41/W38 -> 0.038461538 | X42: =X41/X38 -> 0.051219512 | Y42: =Y41/Y38 -> 0.058298632 | Z42: =Z41/Z38 -> -0.14179104 | AA42: =AA41/AA38 -> -0.11058824 | ... AJ42: =AJ41/AJ38 -> -0.0012376238 | AK42: =(AI41+AJ41)/(AJ38+AI38) -> -0.006477483 | AN42: =AN41/AN38 -> 0.060030395 | AO42: =AO41/AO38 -> 0.087301587 | AP42: =AP41/AP38 -> 0.05480277 | AQ42: =AQ41/AQ38 -> -0.12799168 | AR42: =AR41/AR38 -> -0.12474576 | AS42: =AS41/AS38 -> -0.24570273 | AT42: =AT41/AT38 -> -0.21962051 | AU42: =AU41/AU38 -> -0.0059269015 | AV42: =((AU42/AN42)^(1/(2024-2017)))-1 -> -1.7183745
...

Sheet Acquisitions
